Workbook

Sheet 当前用例与补测
A2: SN318 W2 当前用例与补测
A3: 整理日期 | B3: 2026-10-14 | C3: 工作周期 | D3: W2 10/12–10/16
A5: 记录总数 | B5: 主数据复核数 | C5: 通过 | D5: 不通过 | E5: 计数说明
A6: =COUNTA(A17:A157) -> 141 | B6: =COUNTIFS(E17:E157,"本轮已复核") -> 31 | C6: =COUNTIFS(E17:E157,"本轮已复核",D17:D157,"通过") -> 4 | D6: =COUNTIFS(E17:E157,"本轮已复核",D17:D157,"不通过") -> 23 | E6: 23条失败中20条关联R09，失败用例与独立问题分别统计。
A8: 受阻 | B8: 其他业务未复核 | C8: 模板未重跑 | D8: 主数据确认问题数 | E8: 历史保留
A9: =COUNTIFS(E17:E157,"本轮已复核",D17:D157,"受阻") -> 4 | B9: =COUNTIFS(E17:E157,"本轮未复核") -> 70 | C9: =COUNTIFS(E17:E157,"本轮未重跑") -> 40 | D9: =SUM(COUNTIFS(整改跟进!B11:B29,"已证实规范差异",整改跟进!F11:F29,"主数据轮次已核对"),COUNTIFS(整改跟进!B11:B29,"已证实交互差异",整改跟进!F11:F29,"主数据轮次已核对")) -> 6 | E9: 后四表原样保留；模板结果属于旧版本。
A11: 主数据执行基线 | B11: fd786de / dirty-8cdf1453 | C11: 模板历史基线 | D11: b2efcdb / dirty-5c6bc530
A12: 本版未新增页面执行 | B12: 黄色栏由人工填写 | C12: 证据入口 | D12: 打开证据索引
A13: 执行环境 | B13: 本地Mock / demo | C13: 规范来源 | D13: 沿用10/14快照，本次未刷新
A14: 本周建议 | B14: 10/15补齐判据/样例 | C14: 10/16建议 | D14: 汇总整改及剩余缺口；日期待确认
A16: 用例ID | B16: W2工作包 | C16: 用例名称 | D16: 最近执行结果 | E16: 主数据轮次覆盖 | F16: 最近执行基线 | G16: 变化或判定摘要 | H16: 关联问题ID | I16: 步骤与补测入口 | J16: 原人工复核 | K16: 本轮人工复核 | L16: 复核人 | M16: 复核时间 | N16: 下一步
A17: UI-W2-50-1 | B17: W2-50 | C17: 费用项新增操作归属当前基础配置列表 | D17: 受阻 | E17: 本轮已复核 | F17: fd786de / dirty-8cdf1453 | G17: 产品确认费用类型、分组、默认币种字段映射及采纳设计；对应D01。 | H17: W2-D01 | I17: 查看步骤/补测 | N17: 先补齐具体判据/样例，再复测
A18: UI-W2-50-2 | B18: W2-50 | C18: 费用项长编码及重复提示不会丢失编辑内容 | D18: 不通过 | E18: 本轮已复核 | F18: fd786de / dirty-8cdf1453 | G18: 重复FREIGHT只出现全局Toast“记录已存在，请检查编码或关联对象”，编码字段下没有对应重复错误，未满足本用例“提示关联编码字段”的预期；其他输入保留。 | H18: W2-G04 W2-MR01 | I18: 查看步骤/补测 | N18: 整改后复测，并补齐受阻分支
A19: UI-W2-51-1 | B19: W2-51 | C19: 币种与汇率视图切换后方向和单位明确 | D19: 不通过 | E19: 本轮已复核 | F19: fd786de / dirty-8cdf1453 | G19: 汇率视图源币种/目标币种、直接倍率及生效日/结束日可识别，但7.1234实际内层左对齐，违反本步骤数值右对齐要求。 | H19: W2-R11 | I19: 查看步骤/补测 | N19: 整改后复测，并补齐受阻分支
A20: UI-W2-51-2 | B20: W2-51 | C20: 极小汇率及空零值按批准精度显示 | D20: 受阻 | E20: 本轮已复核 | F20: fd786de / dirty-8cdf1453 | G20: 批准的空/零显示口径及0、空样例。；批准显示精度及极值/超精度样例。；长币种名及全文读取样例。 | H20: W2-D02 W2-G02 | I20: 查看步骤/补测 | N20: 先补齐具体判据/样例，再复测
A21: UI-W2-56-1 | B21: W2-56 | C21: 业务字典主分类和子列表的新增归属清楚 | D21: 受阻 | E21: 本轮已复核 | F21: fd786de / dirty-8cdf1453 | G21: 补业务字典PRD映射及专项分类采纳稿；不阻塞已明确普通UI步骤。 | H21: W2-G03 | I21: 查看步骤/补测 | N21: 先补齐具体判据/样例，再复测
A22: UI-W2-56-2 | B22: W2-56 | C22: 长字典分类和过量Tabs的替代承载可操作 | D22: 受阻 | E22: 本轮已复核 | F22: fd786de / dirty-8cdf1453 | G22: 批准的>7项/长类别替代承载设计及样例。；专项类别样例。；专项承载样例及批准键盘/ARIA判据。 | H22: W2-G02 | I22: 查看步骤/补测 | N22: 先补齐具体判据/样例，再复测
A23: UI-M1-001 | B23: M1公共 | C23: 国家列表查询无结果与重置恢复 | D23: 不通过 | E23: 本轮已复核 | F23: fd786de / dirty-8cdf1453 | G23: 筛选无结果显示“暂无国家数据”，没有“未找到相关结果/请调整筛选条件”的说明及清空筛选引导；工具栏重置仍可用。 | H23: W2-R09 | I23: 查看步骤/补测 | N23: 整改后复测，并补齐受阻分支
A24: UI-M1-002 | B24: M1公共 | C24: 省/州列表查询无结果与重置恢复 | D24: 不通过 | E24: 本轮已复核 | F24: fd786de / dirty-8cdf1453 | G24: 筛选无结果显示“暂无省 / 州数据”，没有“未找到相关结果/请调整筛选条件”的说明及清空筛选引导；工具栏重置仍可用。 | H24: W2-R09 | I24: 查看步骤/补测 | N24: 整改后复测，并补齐受阻分支
A25: UI-M1-003 | B25: M1公共 | C25: 城市列表查询无结果与重置恢复 | D25: 不通过 | E25: 本轮已复核 | F25: fd786de / dirty-8cdf1453 | G25: 筛选无结果显示“暂无城市数据”，没有“未找到相关结果/请调整筛选条件”的说明及清空筛选引导；工具栏重置仍可用。 | H25: W2-R09 | I25: 查看步骤/补测 | N25: 整改后复测，并补齐受阻分支
A26: UI-M1-004 | B26: M1公共 | C26: 区县列表查询无结果与重置恢复 | D26: 不通过 | E26: 本轮已复核 | F26: fd786de / dirty-8cdf1453 | G26: 筛选无结果显示“暂无区县数据”，没有“未找到相关结果/请调整筛选条件”的说明及清空筛选引导；工具栏重置仍可用。 | H26: W2-R09 | I26: 查看步骤/补测 | N26: 整改后复测，并补齐受阻分支
A27: UI-M1-005 | B27: M1公共 | C27: 邮编列表查询无结果与重置恢复 | D27: 不通过 | E27: 本轮已复核 | F27: fd786de / dirty-8cdf1453 | G27: 筛选无结果显示“暂无邮编数据”，没有“未找到相关结果/请调整筛选条件”的说明及清空筛选引导；工具栏重置仍可用。 | H27: W2-R09 | I27: 查看步骤/补测 | N27: 整改后复测，并补齐受阻分支
A28: UI-M1-006 | B28: M1公共 | C28: 机场列表查询无结果与重置恢复 | D28: 不通过 | E28: 本轮已复核 | F28: fd786de / dirty-8cdf1453 | G28: 筛选无结果显示“暂无机场数据”，没有“未找到相关结果/请调整筛选条件”的说明及清空筛选引导；工具栏重置仍可用。 | H28: W2-R09 | I28: 查看步骤/补测 | N28: 整改后复测，并补齐受阻分支
... A44: UI-M1-022 | B44: W2-50 | C44: 费用项空提交及重复编码反馈 | D44: 通过 | E44: 本轮已复核 | F44: fd786de / dirty-8cdf1453 | G44: 受阻改为通过：本轮捕获完整重复反馈、输入保留与解锁；字段关联错误另见UI-W2-50-2。 | H44: W2-D01 | I44: 查看步骤/补测 | N44: 变更影响时回归
A45: UI-M1-023 | B45: W2-51 | C45: 币种编辑编码不可修改 | D45: 通过 | E45: 本轮已复核 | F45: fd786de / dirty-8cdf1453 | G45: 原步骤已验证；仅限记录的Mock范围 | I45: 查看步骤/补测 | N45: 变更影响时回归
A46: UI-M1-024 | B46: W2-51 | C46: 已生效汇率版本维护按M1呈现 | D46: 通过 | E46: 本轮已复核 | F46: fd786de / dirty-8cdf1453 | G46: M1只读/取消行为通过；产品版本、审批和删除口径仍待D02裁决。 | H46: W2-D02 | I46: 查看步骤/补测 | N46: 变更影响时回归
A47: UI-M1-025 | B47: M1公共 | C47: 基础配置汇率公共视觉规范 | D47: 不通过 | E47: 本轮已复核 | F47: fd786de / dirty-8cdf1453 | G47: 查询按钮32px高、圆角2px，预期8px。；正文#1A2130；ratio 7.1234的实际内层为left，操作内层居中、间距4px。预期正文#4B5564、数字右对齐、操作左对齐。 | H47: W2-D03 W2-R01 W2-R03 W2-R04 W2-R11 | I47: 查看步骤/补测 | N47: 整改后复测，并补齐受阻分支
A48: UI-W2-01-1 | B48: W2-01 | C48: 服务单元列表筛选无结果后可重置恢复 | D48: 未执行 | E48: 本轮未复核 | F48: 尚无页面执行基线 | G48: 本轮未复核；后续先核对实际交付页面、原判据与样例 | I48: 查看步骤/补测 | N48: 按新版本与交付页面安排重测
A49: UI-W2-01-2 | B49: W2-01 | C49: 服务单元长名称在宽表滚动后仍可识别 | D49: 未执行 | E49: 本轮未复核 | F49: 尚无页面执行基线 | G49: 本轮未复核；后续先核对实际交付页面、原判据与样例 | I49: 查看步骤/补测 | N49: 按新版本与交付页面安排重测
A50: UI-W2-02-1 | B50: W2-02 | C50: 服务单元勾选与取消后批量栏状态一致 | D50: 未执行 | E50: 本轮未复核 | F50: 尚无页面执行基线 | G50: 本轮未复核；后续先核对实际交付页面、原判据与样例 | I50: 查看步骤/补测 | N50: 按新版本与交付页面安排重测
A51: UI-W2-02-2 | B51: W2-02 | C51: 服务单元混合状态批量操作的失败反馈清楚 | D51: 未执行 | E51: 本轮未复核 | F51: 尚无页面执行基线 | G51: 本轮未复核；后续先核对实际交付页面、原判据与样例 | I51: 查看步骤/补测 | N51: 按新版本与交付页面安排重测
A52: UI-W2-03-1 | B52: W2-03 | C52: 服务单元新建与编辑页面的操作归属清楚 | D52: 未执行 | E52: 本轮未复核 | F52: 尚无页面执行基线 | G52: 本轮未复核；后续先核对实际交付页面、原判据与样例 | I52: 查看步骤/补测 | N52: 按新版本与交付页面安排重测
A53: UI-W2-03-2 | B53: W2-03 | C53: 服务单元长表单的错误提示与取消路径可用 | D53: 未执行 | E53: 本轮未复核 | F53: 尚无页面执行基线 | G53: 本轮未复核；后续先核对实际交付页面、原判据与样例 | I53: 查看步骤/补测 | N53: 按新版本与交付页面安排重测
A54: UI-W2-04-1 | B54: W2-04 | C54: 服务单元详情的只读展示与返回路径明确 | D54: 未执行 | E54: 本轮未复核 | F54: 尚无页面执行基线 | G54: 本轮未复核；后续先核对实际交付页面、原判据与样例 | I54: 查看步骤/补测 | N54: 按新版本与交付页面安排重测
A55: UI-W2-04-2 | B55: W2-04 | C55: 服务单元长详情切换对象后不残留旧内容 | D55: 未执行 | E55: 本轮未复核 | F55: 尚无页面执行基线 | G55: 本轮未复核；后续先核对实际交付页面、原判据与样例 | I55: 查看步骤/补测 | N55: 按新版本与交付页面安排重测
A56: UI-W2-05-1 | B56: W2-05 | C56: 服务单元启停确认能够说明对象与风险 | D56: 未执行 | E56: 本轮未复核 | F56: 尚无页面执行基线 | G56: 本轮未复核；后续先核对实际交付页面、原判据与样例 | I56: 查看步骤/补测 | N56: 按新版本与交付页面安排重测
A57: UI-W2-05-2 | B57: W2-05 | C57: 服务单元被引用或并发改变时能恢复操作 | D57: 未执行 | E57: 本轮未复核 | F57: 尚无页面执行基线 | G57: 本轮未复核；后续先核对实际交付页面、原判据与样例 | I57: 查看步骤/补测 | N57: 按新版本与交付页面安排重测
A58: UI-W2-07-1 | B58: W2-07 | C58: 服务组合列表与详情入口的层级一致 | D58: 未执行 | E58: 本轮未复核 | F58: 尚无页面执行基线 | G58: 本轮未复核；后续先核对实际交付页面、原判据与样例 | I58: 查看步骤/补测 | N58: 按新版本与交付页面安排重测
A59: UI-W2-07-2 | B59: W2-07 | C59: 服务组合零条及末页数据的分页展示正确 | D59: 未执行 | E59: 本轮未复核 | F59: 尚无页面执行基线 | G59: 本轮未复核；后续先核对实际交付页面、原判据与样例 | I59: 查看步骤/补测 | N59: 按新版本与交付页面安排重测
... A117: UI-W2-65-2 | B117: W2-65 | C117: 长日志无结果无权限和失败态的呈现不同 | D117: 未执行 | E117: 本轮未复核 | F117: 尚无页面执行基线 | G117: 本轮未复核；后续先核对实际交付页面、原判据与样例 | I117: 查看步骤/补测 | N117: 按新版本与交付页面安排重测
...

Sheet 整改跟进
A2: SN318 W2 整改跟进
A4: 清单范围 | B4: 规范差异、待裁决、样例缺口 | C4: 新增登记 | D4: G03/G04拆分旧受阻条件 | E4: 历史保留 | F4: 原修改清单不覆盖 | G4: 填报说明 | H4: 黄色栏由责任方填写 | I4: 未分派人员与日期不虚填
A6: 关闭条件 | B6: 修改完成且复测通过 | C6: 仍有条件未齐 | D6: 继续显示待补齐 | E6: 记录分工 | F6: 模型结果与人工复核分栏 | G6: 版本限制 | H6: 未重跑的条目保留旧基线 | I6: 主数据通过不替代产品裁决
A8: 建议推进 | B8: P1差异优先整改 | C8: 判据确认 | D8: 产品/设计确认冲突与范围 | E8: 样例补齐 | F8: 开发提供测试条件 | G8: 复测安排 | H8: 条件齐备后测试介入 | I8: 具体人员、日期待填写
A10: 问题ID | B10: 类型 | C10: 等级 | D10: 页面或对象 | E10: 跟进状态 | F10: 本轮复核覆盖 | G10: 实际差异或复核表现 | H10: 修改或补齐建议 | I10: 验收标准 | J10: 关联用例ID | K10: 证据链接 | L10: 缺条件 | M10: 建议责任角色 | N10: 责任人 | O10: 计划完成日期 | P10: 采用或修复版本 | Q10: 复测日期 | R10: 复测结果 | S10: 复测证据 | T10: 关闭核对
A11: W2-R01 | B11: 已证实规范差异 | C11: P2 | D11: 模板/基础配置/按钮示例 | E11: 待整改复测 | F11: 主数据轮次已核对 | G11: 主数据查询按钮仍2px；模板范围未复测。证据C03-rate-visual。 | H11: 检查公共按钮Token及square类覆盖 | I11: 四类默认按钮32px高、8px圆角；文字不裁切，hover/active尺寸不跳变 | J11: UI-M1-025 UI-TPL-001 UI-TPL-032 | K11: 查看 C03-rate-visual | M11: 前端开发整改；测试复测 | T11: =IF(E11<>"已关闭","未关闭",IF(L11<>"","仍有缺条件",IF(R11<>"通过","缺通过复测",IF(OR(P11="",Q11="",S11=""),"缺版本/日期/证据","关闭资料齐备")))) -> 未关闭
A12: W2-R02 | B12: 已证实规范差异 | C12: P2 | D12: /demo/list | E12: 待整改复测 | F12: 本轮未复核 | G12: 本轮没有重跑该问题对应页面或异常分支；原整改/复测状态保留。 | H12: 检查标准页头垂直间距及行高 | I12: 标准页头94px、面包屑18px，标题与按钮底部对齐 | J12: UI-TPL-002 | K12: 查看 T01-list-baseline、T13-container-metrics | M12: 前端开发整改；测试复测 | T12: =IF(E12<>"已关闭","未关闭",IF(L12<>"","仍有缺条件",IF(R12<>"通过","缺通过复测",IF(OR(P12="",Q12="",S12=""),"缺版本/日期/证据","关闭资料齐备")))) -> 未关闭
A13: W2-R03 | B13: 已证实规范差异 | C13: P2 | D13: 模板操作列/汇率公共表格 | E13: 待整改复测 | F13: 主数据轮次已核对 | G13: 主数据操作仍居中、gap4px；模板范围未复测。证据C03-rate-visual。 | H13: 统一公共表格操作容器，复测固定列边界 | I13: 操作左对齐、文字按钮间距16px；Tablet固定列无重叠 | J13: UI-M1-025 UI-TPL-003 UI-TPL-005 | K13: 查看 C03-rate-metrics | M13: 前端开发整改；测试复测 | T13: =IF(E13<>"已关闭","未关闭",IF(L13<>"","仍有缺条件",IF(R13<>"通过","缺通过复测",IF(OR(P13="",Q13="",S13=""),"缺版本/日期/证据","关闭资料齐备")))) -> 未关闭
A14: W2-R04 | B14: 已证实规范差异 | C14: P2 | D14: 模板/汇率普通正文 | E14: 待整改复测 | F14: 主数据轮次已核对 | G14: 主数据普通正文仍#1A2130；模板范围未复测。证据C03-rate-metrics。 | H14: 检查正文Token被组件默认字色覆盖 | I14: 普通正文#4B5564；标题与状态语义色保留 | J14: UI-M1-025 UI-TPL-004 | K14: 查看 C03-rate-metrics | M14: 前端开发整改；测试复测 | T14: =IF(E14<>"已关闭","未关闭",IF(L14<>"","仍有缺条件",IF(R14<>"通过","缺通过复测",IF(OR(P14="",Q14="",S14=""),"缺版本/日期/证据","关闭资料齐备")))) -> 未关闭
A15: W2-R05 | B15: 已证实规范差异 | C15: P2 | D15: /demo/list 运单链接 | E15: 待整改复测 | F15: 本轮未复核 | G15: 本轮没有重跑该问题对应页面或异常分支；原整改/复测状态保留。 | H15: 按现行链接Token统一 | I15: 默认链接#046EFC，hover/active使用规定色，状态含义不被覆盖 | J15: UI-TPL-004 | K15: 查看 T01-list-baseline | M15: 前端开发整改；测试复测 | T15: =IF(E15<>"已关闭","未关闭",IF(L15<>"","仍有缺条件",IF(R15<>"通过","缺通过复测",IF(OR(P15="",Q15="",S15=""),"缺版本/日期/证据","关闭资料齐备")))) -> 未关闭
A16: W2-R06 | B16: 已证实规范差异 | C16: P1 | D16: /demo/list/form Tablet | E16: 待整改复测 | F16: 本轮未复核 | G16: 本轮没有重跑该问题对应页面或异常分支；原整改/复测状态保留。 | H16: 检查Tablet断点与表单列配置 | I16: 768≤宽<1280采用单列、标签在上、padding16；底栏键盘可达、无根级横溢；1280恢复Desktop | J16: UI-TPL-022 UI-TPL-037 | K16: 查看 T27-form-tablet、T40-form-1279、T41-form-768 | M16: 前端开发整改；测试复测 | T16: =IF(E16<>"已关闭","未关闭",IF(L16<>"","仍有缺条件",IF(R16<>"通过","缺通过复测",IF(OR(P16="",Q16="",S16=""),"缺版本/日期/证据","关闭资料齐备")))) -> 未关闭
A17: W2-R07 | B17: 已证实交互缺陷 | C17: P1 | D17: /demo/list 查询 | E17: 待整改复测 | F17: 本轮未复核 | G17: 本轮没有重跑该问题对应页面或异常分支；原整改/复测状态保留。 | H17: 让查询按钮绑定请求状态并防止重复请求 | I17: 查询启动立即loading并不可再次触发；保留筛选，完成/失败后解除loading | J17: UI-TPL-028 | K17: 查看 T02-query-loading | L17: 需补请求计数/slow及异常恢复样例 | M17: 前端开发整改；测试复测 | T17: =IF(E17<>"已关闭","未关闭",IF(L17<>"","仍有缺条件",IF(R17<>"通过","缺通过复测",IF(OR(P17="",Q17="",S17=""),"缺版本/日期/证据","关闭资料齐备")))) -> 未关闭
A18: W2-R08 | B18: 已证实交互差异 | C18: P1 | D18: /demo/list reload | E18: 待整改复测 | F18: 本轮未复核 | G18: 本轮没有重跑该问题对应页面或异常分支；原整改/复测状态保留。 | H18: 核对Mock登录状态恢复与路由准入约定 | I18: 本地测试账号刷新仍处于/demo/list且导航一致、详情可用；若Mock不支持持久登录，应批准修改原验收前置并明确说明 | J18: UI-TPL-019 | K18: 查看 T35-refresh-login | L18: Mock会话持久性验收口径需明确 | M18: 前端开发整改；测试复测 | T18: =IF(E18<>"已关闭","未关闭",IF(L18<>"","仍有缺条件",IF(R18<>"通过","缺通过复测",IF(OR(P18="",Q18="",S18=""),"缺版本/日期/证据","关闭资料齐备")))) -> 未关闭
A19: W2-R09 | B19: 已证实规范差异 | C19: P1 | D19: 18个M1列表+2个关联子表 | E19: 待整改复测 | F19: 主数据轮次已核对 | G19: 18列表+2子表无结果仍暂无××数据，重置恢复已验证。见UI-M1-001至020。 | H19: 按是否有筛选区分首次无数据与无结果，共用空态组件 | I19: 查询0结果保留条件并显示未找到相关结果/调整筛选及重置入口；重置恢复原对象；首次无数据仍按权限引导新增 | J19: UI-M1-001 UI-M1-002 UI-M1-003 UI-M1-004 UI-M1-005 UI-M1-006 UI-M1-007 UI-M1-008 UI-M1-009 UI-M1-010 UI-M1-011 UI-M1-012 UI-M1-013 UI-M1-014 UI-M1-015 UI-M1-016 UI-M1-017 UI-M1-018 UI-M1-019 UI-M1-020 | K19: 查看 M02-country-empty、R10-empty、R11-empty、R12-empty、R13-empty、R14-empty、R15-empty、R16-empty、R17-empty、R18-empty、R19-empty、R20-empty、R4-empty、R5-empty、R6-empty、R7-empty、R8-empty、R9-empty、S19-relation-empty、S20-relation-empty | M19: 前端开发整改；测试复测 | T19: =IF(E19<>"已关闭","未关闭",IF(L19<>"","仍有缺条件",IF(R19<>"通过","缺通过复测",IF(OR(P19="",Q19="",S19=""),"缺版本/日期/证据","关闭资料齐备")))) -> 未关闭
A20: W2-R10 | B20: 已证实说明与交互不一致 | C20: P2 | D20: /demo/components Upload | E20: 待整改复测 | F20: 本轮未复核 | G20: 本轮没有重跑该问题对应页面或异常分支；原整改/复测状态保留。 | H20: 明确待上传/上传中状态；按已声明显式提交方案设置开始动作，或经产品批准修订说明 | I20: 选择后仅待上传，明确开始才显示进度；取消终止，重试可成功；本条未验证实际网络文件传输 | J20: UI-TPL-038 | K20: 查看 C08-upload-file-selected、C09-upload-auto-error、C10-upload-retry-progress、C11-upload-cancel | L20: 需要批准上传触发方案及可成功重试样例 | M20: 前端开发整改；测试复测 | T20: =IF(E20<>"已关闭","未关闭",IF(L20<>"","仍有缺条件",IF(R20<>"通过","缺通过复测",IF(OR(P20="",Q20="",S20=""),"缺版本/日期/证据","关闭资料齐备")))) -> 未关闭
A21: W2-R11 | B21: 已证实规范差异 | C21: P2 | D21: 基础配置汇率ratio | E21: 待整改复测 | F21: 主数据轮次已核对 | G21: 汇率7.1234实际内层仍左对齐。证据C03-rate-metrics。 | H21: 为ratio配置数字右对齐，保留PRD/M1精度 | I21: 汇率数字右对齐；不改变精度迁就宽度，空与0可区分 | J21: UI-M1-025 UI-W2-51-1 | K21: 查看 C03-rate-metrics | M21: 前端开发整改；测试复测 | T21: =IF(E21<>"已关闭","未关闭",IF(L21<>"","仍有缺条件",IF(R21<>"通过","缺通过复测",IF(OR(P21="",Q21="",S21=""),"缺版本/日期/证据","关闭资料齐备")))) -> 未关闭
A22: W2-D01 | B22: 规范/范围待裁决 | C22: P1 | D22: 费用项字段 | E22: 待确认 | F22: 主数据轮次已核对 | G22: 费用项仍分组编码/默认币种文本，产品PRD与M1映射待裁决。F04/F07。 | H22: 确认M1字段是否映射到本周产品PRD；批准后再定修复范围 | I22: 产品确认字段映射/字典来源/必填与变更审批；批准范围内选择控件符合稿 | J22: UI-M1-021 UI-M1-022 UI-W2-50-1 | K22: 查看 F04-fee-create、F07-fee-duplicate-result | L22: 产品批准M1与PRD映射 | M22: 产品/设计裁决；测试核对 | T22: =IF(E22<>"已关闭","未关闭",IF(L22<>"","仍有缺条件",IF(R22<>"通过","缺通过复测",IF(OR(P22="",Q22="",S22=""),"缺版本/日期/证据","关闭资料齐备")))) -> 未关闭
A23: W2-D02 | B23: 规范/范围待裁决 | C23: P1 | D23: 币种与汇率 | E23: 待确认 | F23: 主数据轮次已核对 | G23: M1只读/结束区间可调/无删除已验证，但产品版本/删除/审批裁决未完成。C04-C06。 | H23: 确定本周采用版本维护、审批与删除口径 | I23: 产品签定一种一致口径，补变更版本/权限/提交异常样例；按批准口径复测 | J23: UI-M1-024 UI-W2-51-2 | K23: 查看 C04-rate-edit、C05-rate-end-unsaved、C06-rate-cancel | L23: 产品对冲突条款作裁决 | M23: 产品/设计裁决；测试核对 | T23: =IF(E23<>"已关闭","未关闭",IF(L23<>"","仍有缺条件",IF(R23<>"通过","缺通过复测",IF(OR(P23="",Q23="",S23=""),"缺版本/日期/证据","关闭资料齐备")))) -> 未关闭
A24: W2-D03 | B24: 体验说明待确认 | C24: P2 | D24: 基础配置对象区 | E24: 待确认 | F24: 主数据轮次已核对 | G24: 本地仍启用Mock，界面仍写“选择对象查看正式数据”。R18-loaded。 | H24: 确认Mock环境标识及文案 | I24: 本地测试界面能识别模拟数据来源；该文案不当作生产数据证明 | J24: UI-M1-025 | K24: 查看 R18-loaded | L24: Mock环境标识方案 | M24: 产品/设计裁决；测试核对 | T24: =IF(E24<>"已关闭","未关闭",IF(L24<>"","仍有缺条件",IF(R24<>"通过","缺通过复测",IF(OR(P24="",Q24="",S24=""),"缺版本/日期/证据","关闭资料齐备")))) -> 未关闭
A25: W2-G01 | B25: 样例/批准策略缺口 | C25: P1 | D25: 查询/表单/异常页 | E25: 待补齐 | F25: 本轮未复核 | G25: 本轮没有重跑该问题对应页面或异常分支；原整改/复测状态保留。 | H25: 提供可在页面触发的受控响应及恢复按钮/数据 | I25: 逐分支记录真实UI动作、响应和恢复；不以直接/403、/500路由替代 | J25: UI-TPL-028 UI-TPL-035 UI-TPL-039 | K25: 查看 E01-403-display、E03-500-display | L25: 响应样例与初始化/提交触发方式 | M25: 产品/设计确认；开发提供样例；测试复测 | T25: =IF(E25<>"已关闭","未关闭",IF(L25<>"","仍有缺条件",IF(R25<>"通过","缺通过复测",IF(OR(P25="",Q25="",S25=""),"缺版本/日期/证据","关闭资料齐备")))) -> 未关闭
A26: W2-G02 | B26: 样例/批准策略缺口 | C26: P2 | D26: 组件/表单/导航 | E26: 待补齐 | F26: 主数据轮次已核对 | G26: 专项分类长文/>7项及键盘路径、极值数据等仍缺；已可执行普通UI步骤分别取证。 | H26: 先补批准策略，再提供Tabs计数/长文/三态/请求计数等可执行样例 | I26: 按每条需要条件补齐后逐步复测；不得把DOM存在/历史通过替代新执行 | J26: UI-TPL-013 UI-TPL-014 UI-TPL-016 UI-TPL-020 UI-TPL-021 UI-TPL-023 UI-TPL-026 UI-TPL-027 UI-TPL-029 UI-TPL-030 UI-TPL-031 UI-TPL-032 UI-TPL-033 UI-TPL-034 UI-TPL-036 UI-TPL-038 UI-W2-51-2 UI-W2-56-2 | K26: 查看 R17-loaded、R20-loaded | L26: 逐条缺条件见用例记录 | M26: 产品/设计确认；开发提供样例；测试复测 | T26: =IF(E26<>"已关闭","未关闭",IF(L26<>"","仍有缺条件",IF(R26<>"通过","缺通过复测",IF(OR(P26="",Q26="",S26=""),"缺版本/日期/证据","关闭资料齐备")))) -> 未关闭
A27: W2-MR01 | B27: 已证实交互差异 | C27: P2 | D27: 费用项新增重复编码 | E27: 待整改复测 | F27: 主数据轮次已核对 | G27: 只弹全局重复Toast，编码字段未显示关联错误 | H27: 将编码唯一性错误映射到编码字段下，保留其他输入 | I27: 重复FREIGHT时编码字段下定位重复原因；输入保留、保存解锁 | J27: UI-W2-50-2 | K27: 查看 F07-fee-duplicate-result | L27: 编码上限L与其他失败样例另列受阻 | M27: 前端开发整改；测试复测 | T27: =IF(E27<>"已关闭","未关闭",IF(L27<>"","仍有缺条件",IF(R27<>"通过","缺通过复测",IF(OR(P27="",Q27="",S27=""),"缺版本/日期/证据","关闭资料齐备")))) -> 未关闭
A28: W2-G03 | B28: 执行条件缺口 | C28: P1 | D28: 业务字典专项范围 | E28: 待补齐 | F28: 主数据轮次已核对 | G28: 业务字典PRD映射与专项分类采纳稿未确认；普通新增/取消步骤已有证据。 | H28: 产品/设计确认业务字典字段、分类及本周纳入范围；测试按批准口径核对。 | I28: PRD与采纳稿可追溯到本周工作包；已记录的普通UI步骤不被重复记成未执行。 | J28: UI-W2-56-1 | K28: 查看 D01-dictionary-create、D02-dictionary-cancel | L28: 业务字典PRD映射与专项分类采纳稿未确认；普通新增/取消步骤已有证据。 | M28: 产品/设计确认；开发提供样例；测试复测 | T28: =IF(E28<>"已关闭","未关闭",IF(L28<>"","仍有缺条件",IF(R28<>"通过","缺通过复测",IF(OR(P28="",Q28="",S28=""),"缺版本/日期/证据","关闭资料齐备")))) -> 未关闭
A29: W2-G04 | B29: 执行条件缺口 | C29: P2 | D29: 费用项边界与失败响应 | E29: 待补齐 | F29: 主数据轮次已核对 | G29: 编码上限L及非重复编码的可控保存失败响应缺失。 | H29: 产品确认L；开发提供L-1/L/L+1及非重复保存失败样例；测试逐分支复测。 | I29: 边界限制按批准L呈现；旧字段错误清除，新失败提示明确、输入保留、保存解锁。 | J29: UI-W2-50-2 | K29: 查看 F04-fee-create、F07-fee-duplicate-result | L29: 编码上限L及非重复编码的可控保存失败响应缺失。 | M29: 产品/设计确认；开发提供样例；测试复测 | T29: =IF(E29<>"已关闭","未关闭",IF(L29<>"","仍有缺条件",IF(R29<>"通过","缺通过复测",IF(OR(P29="",Q29="",S29=""),"缺版本/日期/证据","关闭资料齐备")))) -> 未关闭

Sheet 业务UI与交互用例
A1: 用例名称 | B1: 所属模块 | C1: 前置条件 | D1: 步骤描述 | E1: 预期结果 | F1: 用例等级 | G1: 备注 | H1: 执行状态 | I1: 实际结果/证据 | J1: 人工二次复核 | K1: 本次原候选执行状态 | L1: 本次说明（原H/I保留） | M1: 本次Build/覆盖 | N1: 复核状态（fd786de 主数据轮次） | O1: 复核实际/证据（保留原H-M） | P1: 本轮Build与范围 | Q1: 相对上一轮的变化
A2: 服务单元列表筛选无结果后可重置恢复 | B2: /SN318/W2/服务单元/服务单元列表与筛选/interaction | C2: [1]使用具备“服务单元”页面权限的测试账号，进入本批提测环境。 [2]实际业务页面已交付且入口可访问；通用规范已有明确要求的步骤可先走查。 [3]记录Build、URL、角色及样例；专项PRD/设计稿未补齐仅阻塞依赖其判据的步骤。缺入口时整条受阻；缺状态或样例时逐步说明，其他步骤照常取证。 [4]列表有可匹配记录；准备一组有效筛选条件及一组必定无结果的条件。 | D2: [1]从菜单进入服务单元列表，查看页头、筛选区和主操作。 [2]填写有效条件，点击“查询”，观察列表刷新过程。 [3]改为无结果条件，再次点击“查询”。 [4]点击“重置”，重新查看列表及筛选控件。 | E2: [1]页面标题、面包屑及当前菜单一致；主操作属于当前列表，筛选控件未被强行拉伸。 [2]查询过程中有局部刷新反馈；完成后显示对应样例数据，输入条件仍可查看。 [3]显示“未找到相关结果”及调整/清空筛选引导；筛选区保留，不能显示为首次无数据。 [4]筛选恢复批准的初始值，列表退出无结果态；页码、总数及当前数据相互对应。 | F2: P0 | G2: 【设计依据】场景法-筛选与空态恢复 【测试类型】interaction 【追溯信息】用例编号：UI-W2-01-1；原用例：W2-01-1；排期序号1/原表行5 【知识库依据】RV12/RV13/RV14/RV23 【准入状态】按实际交付入口介入；专项缺口逐步记录 【执行范围】检查界面呈现、交互路径与恢复；业务规则正确性沿用功能测试。 【来源边界】业务PRD/专项设计稿未读取；排期“PRD”仅为来源标签。本条为候选用例；通用规范明确要求可先查，业务专项判据须与相应基线核对。 【待补判据】实际筛选字段/初始值、查询及重置是否重新请求、页头创建入口位置（RV23待确认）。未明确的子步骤记受阻。 【审查方式】用例文本及来源自行复核；本轮页面未执行，执行结果另填。 【本周安排】今天输出UI规范审查及修改清单；本周对实际交付页面全面介入UI与交互。异常/边界缺样例逐步受阻，功能验证按原分工。 | H2: 未执行 | K2: 未执行 | L2: 原候选步骤未完整重跑；本次已交付M1补测见下方UI-M1-001–025，不替代本条。 | M2: W2-dev-20261014-5c6bc530 | N2: 未执行 | O2: 本轮聚焦主数据相关31条；本条未复核，K-M旧轮次记录保留。 | P2: W2-master-20261014-fd786de-8cdf1453 本轮未涉及 | Q2: 未重跑；不产生新通过/失败结论。
A3: 服务单元长名称在宽表滚动后仍可识别 | B3: /SN318/W2/服务单元/服务单元列表与筛选/boundary | C3: [1]使用具备“服务单元”页面权限的测试账号，进入本批提测环境。 [2]实际业务页面已交付且入口可访问；通用规范已有明确要求的步骤可先走查。 [3]记录Build、URL、角色及样例；专项PRD/设计稿未补齐仅阻塞依赖其判据的步骤。缺入口时整条受阻；缺状态或样例时逐步说明，其他步骤照常取证。 [4]按PRD长度上限L准备接近上限的中文、英文名称；列表包含足以触发横向滚动的列。 | D3: [1]打开服务单元列表，查看长名称和业务标识列。 [2]悬停被省略的名称，再用键盘定位同一条记录。 [3]将表格向右滚动到最末列，再向左滚回。 [4]分别在1440和1024宽度下重复横向滚动。 | E3: [1]长名称单行省略显示；核心业务标识未被无关字段挤出可视区域。 [2]可通过规范规定的全文提示读取名称；键盘焦点不被截断容器遮挡。 [3]左侧勾选/识别列、右侧操作列固定且内容完整；主体列未覆盖固定列。 [4]滚动发生在表格容器内部；页面不产生额外横向溢出，操作按钮仍可达。 | F3: P0 | G3: 【设计依据】边界值分析-长文本与固定列 【测试类型】boundary 【追溯信息】用例编号：UI-W2-01-2；原用例：W2-01-2；排期序号1/原表行5 【知识库依据】RV16/规范5.8、9.4 【准入状态】按实际交付入口介入；专项缺口逐步记录 【执行范围】检查界面呈现、交互路径与恢复；业务规则正确性沿用功能测试。 【来源边界】业务PRD/专项设计稿未读取；排期“PRD”仅为来源标签。本条为候选用例；通用规范明确要求可先查，业务专项判据须与相应基线核对。 【待补判据】目标名称字段及长度L、长名称样例、左侧勾选/核心标识字段和右侧操作固定列设计、最小支持宽度。未明确的子步骤记受阻。 【审查方式】用例文本及来源自行复核；本轮页面未执行，执行结果另填。 【本周安排】今天输出UI规范审查及修改清单；本周对实际交付页面全面介入UI与交互。异常/边界缺样例逐步受阻，功能验证按原分工。 | H3: 未执行 | K3: 未执行 | L3: 原候选步骤未完整重跑；本次已交付M1补测见下方UI-M1-001–025，不替代本条。 | M3: W2-dev-20261014-5c6bc530 | N3: 未执行 | O3: 本轮聚焦主数据相关31条；本条未复核，K-M旧轮次记录保留。 | P3: W2-master-20261014-fd786de-8cdf1453 本轮未涉及 | Q3: 未重跑；不产生新通过/失败结论。
A4: 服务单元勾选与取消后批量栏状态一致 | B4: /SN318/W2/服务单元/服务单元批量操作/interaction | C4: [1]使用具备“服务单元”页面权限的测试账号，进入本批提测环境。 [2]实际业务页面已交付且入口可访问；通用规范已有明确要求的步骤可先走查。 [3]记录Build、URL、角色及样例；专项PRD/设计稿未补齐仅阻塞依赖其判据的步骤。缺入口时整条受阻；缺状态或样例时逐步说明，其他步骤照常取证。 [4]准备仅一页、恰好3条可选记录的列表；尚未选择记录，避免本条受跨页选择策略干扰。 | D4: [1]进入服务单元列表，查看未选中时的顶部工具栏。 [2]勾选第1条记录，查看批量栏及整行背景。 [3]点击表头全选，再取消其中1行。 [4]点击取消选择。 | E4: [1]默认工具栏可见，批量栏未出现，3行均未选中。 [2]表格顶部显示已选择1项；主体和固定列的选中背景一致。 [3]3行全选后显示已选择3项；取消1行后显示已选择2项，表头呈半选态，行勾选与数量对应。 [4]3行勾选及选中背景清空，批量栏消失，默认工具栏恢复。 | F4: P0 | G4: 【设计依据】状态转换-零选单选全选半选 【测试类型】interaction 【追溯信息】用例编号：UI-W2-02-1；原用例：W2-02-1；排期序号2/原表行6 【知识库依据】RV17/RV18 【准入状态】按实际交付入口介入；专项缺口逐步记录 【执行范围】检查界面呈现、交互路径与恢复；业务规则正确性沿用功能测试。 【来源边界】业务PRD/专项设计稿未读取；排期“PRD”仅为来源标签。本条为候选用例；通用规范明确要求可先查，业务专项判据须与相应基线核对。 【待补判据】单页3条可选记录、顶部批量栏设计和已选择数量文案；跨页范围另由UI-W2-02-2检查。未明确的子步骤记受阻。 【审查方式】用例文本及来源自行复核；本轮页面未执行，执行结果另填。 【本周安排】今天输出UI规范审查及修改清单；本周对实际交付页面全面介入UI与交互。异常/边界缺样例逐步受阻，功能验证按原分工。 | H4: 未执行 | K4: 未执行 | L4: 原候选步骤未完整重跑；本次已交付M1补测见下方UI-M1-001–025，不替代本条。 | M4: W2-dev-20261014-5c6bc530 | N4: 未执行 | O4: 本轮聚焦主数据相关31条；本条未复核，K-M旧轮次记录保留。 | P4: W2-master-20261014-fd786de-8cdf1453 本轮未涉及 | Q4: 未重跑；不产生新通过/失败结论。
A5: 服务单元混合状态批量操作的失败反馈清楚 | B5: /SN318/W2/服务单元/服务单元批量操作/exception | C5: [1]使用具备“服务单元”页面权限的测试账号，进入本批提测环境。 [2]实际业务页面已交付且入口可访问；通用规范已有明确要求的步骤可先走查。 [3]记录Build、URL、角色及样例；专项PRD/设计稿未补齐仅阻塞依赖其判据的步骤。缺入口时整条受阻；缺状态或样例时逐步说明，其他步骤照常取证。 [4]准备可操作/不可操作混合记录及部分失败响应样例；跨页选择策略已写入PRD。 | D5: [1]选中混合状态记录，查看批量按钮及禁用说明。 [2]切换到下一页并修改筛选条件，查看选中对象与数量。 [3]打开批量操作确认，核对对象范围后用前端样例返回部分失败。 [4]定位失败记录，取消选择或按提供入口重试。 | E5: [1]按钮按批准策略显示可用状态；不可操作项的原因可理解，不只用颜色区分。 [2]跨页和筛选后的保留/清空表现符合已批准策略；数量与可操作对象范围一致。 [3]确认展示的范围与勾选一致；结果分别说明成功数和失败数，不把部分失败报成全部成功。 [4]失败对象及原因可定位；结束后按钮解除loading，用户能清空选择或继续处理。 | F5: P0 | G5: 【设计依据】错误推测法-混合对象与部分失败 【测试类型】exception 【追溯信息】用例编号：UI-W2-02-2；原用例：W2-02-2；排期序号2/原表行6 【知识库依据】阶段共识19/规范7.3 【准入状态】按实际交付入口介入；专项缺口逐步记录 【执行范围】检查界面呈现、交互路径与恢复；业务规则正确性沿用功能测试。 【来源边界】业务PRD/专项设计稿未读取；排期“PRD”仅为来源标签。本条为候选用例；通用规范明确要求可先查，业务专项判据须与相应基线核对。 【待补判据】允许批量动作、不可操作项原因、全选范围、跨页/改筛选后的选择策略、部分失败响应与重试入口。未明确的子步骤记受阻。 【异常取证】执行前记录具体响应、切换入口及数据来源；无法从页面触发的异常步骤记受阻，不用直接展示页替代。 【审查方式】用例文本及来源自行复核；本轮页面未执行，执行结果另填。 【本周安排】今天输出UI规范审查及修改清单；本周对实际交付页面全面介入UI与交互。异常/边界缺样例逐步受阻，功能验证按原分工。 | H5: 未执行 | K5: 未执行 | L5: 原候选步骤未完整重跑；本次已交付M1补测见下方UI-M1-001–025，不替代本条。 | M5: W2-dev-20261014-5c6bc530 | N5: 未执行 | O5: 本轮聚焦主数据相关31条；本条未复核，K-M旧轮次记录保留。 | P5: W2-master-20261014-fd786de-8cdf1453 本轮未涉及 | Q5: 未重跑；不产生新通过/失败结论。
A6: 服务单元新建与编辑页面的操作归属清楚 | B6: /SN318/W2/服务单元/新增/编辑服务单元（弹窗）/UI | C6: [1]使用具备“服务单元”页面权限的测试账号，进入本批提测环境。 [2]实际业务页面已交付且入口可访问；通用规范已有明确要求的步骤可先走查。 [3]记录Build、URL、角色及样例；专项PRD/设计稿未补齐仅阻塞依赖其判据的步骤。缺入口时整条受阻；缺状态或样例时逐步说明，其他步骤照常取证。 [4]已确认新增/编辑的承载容器；准备一条允许编辑的服务单元记录。 [5]产品/UI已书面确定本入口采用页面、弹窗还是抽屉，按确认后的容器执行。 | D6: [1]从列表点击“新增服务单元”，查看容器、标题和字段组。 [2]滚动到末尾，再返回顶部，查看保存/取消入口。 [3]取消新增，打开已有记录的“编辑”。 [4]比较新增和编辑的公共字段、帮助文字与主操作位置。 | E6: [1]承载方式与批准稿一致；标题明确为新增，必填/可选字段及分组清楚。 [2]操作区按该容器规范固定或可达；长表单不需要嵌套多层弹窗。 [3]回到原列表后可打开编辑；标题明确为编辑，回显字段与当前对象一致。 [4]相同含义的字段、控件和文案保持一致；只读字段有明确展示，不伪装为可输入。 | F6: P0 | G6: 【设计依据】场景法-内容承载与表单分组 【测试类型】UI 【追溯信息】用例编号：UI-W2-03-1；原用例：W2-03-1；排期序号3/原表行7 【知识库依据】RV06/规范内容承载决策 【准入状态】按实际交付入口介入；专项范围待确认 【执行范围】检查界面呈现、交互路径与恢复；业务规则正确性沿用功能测试。 【来源边界】业务PRD/专项设计稿未读取；排期“PRD”仅为来源标签。本条为候选用例；通用规范明确要求可先查，业务专项判据须与相应基线核对。 【待补判据】新增/编辑承载容器、固定操作区、目标必填字段与长度上限L、离开确认及草稿策略（RV06修改中）。未明确的子步骤记受阻。 【审查方式】用例文本及来源自行复核；本轮页面未执行，执行结果另填。 【本周安排】今天输出UI规范审查及修改清单；本周对实际交付页面全面介入UI与交互。异常/边界缺样例逐步受阻，功能验证按原分工。 | H6: 未执行 | K6: 未执行 | L6: 原候选步骤未完整重跑；本次已交付M1补测见下方UI-M1-001–025，不替代本条。 | M6: W2-dev-20261014-5c6bc530 | N6: 未执行 | O6: 本轮聚焦主数据相关31条；本条未复核，K-M旧轮次记录保留。 | P6: W2-master-20261014-fd786de-8cdf1453 本轮未涉及 | Q6: 未重跑；不产生新通过/失败结论。
A7: 服务单元长表单的错误提示与取消路径可用 | B7: /SN318/W2/服务单元/新增/编辑服务单元（弹窗）/boundary | C7: [1]使用具备“服务单元”页面权限的测试账号，进入本批提测环境。 [2]实际业务页面已交付且入口可访问；通用规范已有明确要求的步骤可先走查。 [3]记录Build、URL、角色及样例；专项PRD/设计稿未补齐仅阻塞依赖其判据的步骤。缺入口时整条受阻；缺状态或样例时逐步说明，其他步骤照常取证。 [4]PRD已给出目标文本字段上限L；准备L-1、L、L+1字符；重要输入的离开策略已确认。 [5]产品/UI已书面确定本入口采用页面、弹窗还是抽屉，按确认后的容器执行。 | D7: [1]打开新增表单，清空一个必填字段，点击“保存”。 [2]修正该字段，分别输入L-1、L和L+1字符，检查计数及超限反馈。 [3]填写其他重要输入，再点击“取消”或浏览器返回。 [4]按批准策略选择保留编辑或确认离开，再次进入该表单。 | E7: [1]相关字段下显示明确必填提示；表单仍保留，错误不会遮盖下一字段或操作区。 [2]有效长度按批准规则可输入；超限被限制或明确提示，具体表现与PRD一致，文本不撑破布局。 [3]离开行为按已确认策略处理；如设计要求确认，明确提供离开/继续编辑两个动作。 [4]保留编辑时内容不丢失；确认离开后的重入内容符合批准策略，不把旧对象输入带入新对象。 | F7: P0 | G7: 【设计依据】边界值分析/场景法-错误修正和离开 【测试类型】boundary 【追溯信息】用例编号：UI-W2-03-2；原用例：W2-03-2；排期序号3/原表行7 【知识库依据】规范5.7/阶段共识22 【准入状态】按实际交付入口介入；专项范围待确认 【执行范围】检查界面呈现、交互路径与恢复；业务规则正确性沿用功能测试。 【来源边界】业务PRD/专项设计稿未读取；排期“PRD”仅为来源标签。本条为候选用例；通用规范明确要求可先查，业务专项判据须与相应基线核对。 【待补判据】新增/编辑承载容器、固定操作区、目标必填字段与长度上限L、离开确认及草稿策略（RV06修改中）。未明确的子步骤记受阻。 【审查方式】用例文本及来源自行复核；本轮页面未执行，执行结果另填。 【本周安排】今天输出UI规范审查及修改清单；本周对实际交付页面全面介入UI与交互。异常/边界缺样例逐步受阻，功能验证按原分工。 | H7: 未执行 | K7: 未执行 | L7: 原候选步骤未完整重跑；本次已交付M1补测见下方UI-M1-001–025，不替代本条。 | M7: W2-dev-20261014-5c6bc530 | N7: 未执行 | O7: 本轮聚焦主数据相关31条；本条未复核，K-M旧轮次记录保留。 | P7: W2-master-20261014-fd786de-8cdf1453 本轮未涉及 | Q7: 未重跑；不产生新通过/失败结论。
A8: 服务单元详情的只读展示与返回路径明确 | B8: /SN318/W2/服务单元/服务单元详情（只读）/UI | C8: [1]使用具备“服务单元”页面权限的测试账号，进入本批提测环境。 [2]实际业务页面已交付且入口可访问；通用规范已有明确要求的步骤可先走查。 [3]记录Build、URL、角色及样例；专项PRD/设计稿未补齐仅阻塞依赖其判据的步骤。缺入口时整条受阻；缺状态或样例时逐步说明，其他步骤照常取证。 [4]服务单元详情Page/Drawer冲突已裁决；准备一条有多组信息的记录。 [5]产品/UI已书面确定本入口采用页面、弹窗还是抽屉，按确认后的容器执行。 | D8: [1]从服务单元列表打开一条详情，查看容器和标题。 [2]逐组查看字段、状态及关联信息。 [3]使用详情提供的关闭/返回入口回到列表。 | E8: [1]采用本入口已裁决的承载方式；标题及对象标识清楚，没有同时出现两套冲突入口。 [2]只读信息按分组展示；只读值不显示误导性输入框、保存按钮或可编辑暗示。 [3]返回原列表上下文；筛选、定位及滚动的表现符合批准设计，不跳到无关页面。 | F8: P1 | G8: 【设计依据】场景法-详情承载与只读语义 【测试类型】UI 【追溯信息】用例编号：UI-W2-04-1；原用例：W2-04-1；排期序号4/原表行8 【知识库依据】RV07/RV22 【准入状态】按实际交付入口介入；专项范围待确认 【执行范围】检查界面呈现、交互路径与恢复；业务规则正确性沿用功能测试。 【来源边界】业务PRD/专项设计稿未读取；排期“PRD”仅为来源标签。本条为候选用例；通用规范明确要求可先查，业务专项判据须与相应基线核对。 【待补判据】详情采用Page还是Drawer（RV07与RV22待裁决）、空值口径、返回后筛选/定位保留范围。未明确的子步骤记受阻。 【审查方式】用例文本及来源自行复核；本轮页面未执行，执行结果另填。 【本周安排】今天输出UI规范审查及修改清单；本周对实际交付页面全面介入UI与交互。异常/边界缺样例逐步受阻，功能验证按原分工。 | H8: 未执行 | K8: 未执行 | L8: 原候选步骤未完整重跑；本次已交付M1补测见下方UI-M1-001–025，不替代本条。 | M8: W2-dev-20261014-5c6bc530 | N8: 未执行 | O8: 本轮聚焦主数据相关31条；本条未复核，K-M旧轮次记录保留。 | P8: W2-master-20261014-fd786de-8cdf1453 本轮未涉及 | Q8: 未重跑；不产生新通过/失败结论。
A9: 服务单元长详情切换对象后不残留旧内容 | B9: /SN318/W2/服务单元/服务单元详情（只读）/boundary | C9: [1]使用具备“服务单元”页面权限的测试账号，进入本批提测环境。 [2]实际业务页面已交付且入口可访问；通用规范已有明确要求的步骤可先走查。 [3]记录Build、URL、角色及样例；专项PRD/设计稿未补齐仅阻塞依赖其判据的步骤。缺入口时整条受阻；缺状态或样例时逐步说明，其他步骤照常取证。 [4]准备记录A（空字段、长地址/备注、多关联项）及内容明显不同的记录B。 [5]产品/UI已书面确定本入口采用页面、弹窗还是抽屉，按确认后的容器执行。 | D9: [1]打开记录A详情，查看空值、长地址和长备注。 [2]展开长文本，滚动到末尾，再收起。 [3]关闭A详情，立即打开记录B。 [4]关闭B详情，查看列表当前定位。 | E9: [1]空值按批准口径显示；超过规范行数的长文本提供展开，未无提示丢失内容。 [2]可完整阅读内容；标题/操作及内容滚动关系符合批准容器，不出现叠层遮挡。 [3]标题、状态、字段值和关联信息均属于B；不短暂或持续显示A的旧详情。 [4]列表上下文按批准稿保留，仍能定位刚查看的对象。 | F9: P1 | G9: 【设计依据】边界值分析-长详情与对象切换 【测试类型】boundary 【追溯信息】用例编号：UI-W2-04-2；原用例：W2-04-2；排期序号4/原表行8 【知识库依据】规范5.11、9.1、9.4 【准入状态】按实际交付入口介入；专项范围待确认 【执行范围】检查界面呈现、交互路径与恢复；业务规则正确性沿用功能测试。 【来源边界】业务PRD/专项设计稿未读取；排期“PRD”仅为来源标签。本条为候选用例；通用规范明确要求可先查，业务专项判据须与相应基线核对。 【待补判据】详情采用Page还是Drawer（RV07与RV22待裁决）、空值口径、返回后筛选/定位保留范围。未明确的子步骤记受阻。 【审查方式】用例文本及来源自行复核；本轮页面未执行，执行结果另填。 【本周安排】今天输出UI规范审查及修改清单；本周对实际交付页面全面介入UI与交互。异常/边界缺样例逐步受阻，功能验证按原分工。 | H9: 未执行 | K9: 未执行 | L9: 原候选步骤未完整重跑；本次已交付M1补测见下方UI-M1-001–025，不替代本条。 | M9: W2-dev-20261014-5c6bc530 | N9: 未执行 | O9: 本轮聚焦主数据相关31条；本条未复核，K-M旧轮次记录保留。 | P9: W2-master-20261014-fd786de-8cdf1453 本轮未涉及 | Q9: 未重跑；不产生新通过/失败结论。
A10: 服务单元启停确认能够说明对象与风险 | B10: /SN318/W2/服务单元/禁用编排/启用 与产品引用关系/interaction | C10: [1]使用具备“服务单元”页面权限的测试账号，进入本批提测环境。 [2]实际业务页面已交付且入口可访问；通用规范已有明确要求的步骤可先走查。 [3]记录Build、URL、角色及样例；专项PRD/设计稿未补齐仅阻塞依赖其判据的步骤。缺入口时整条受阻；缺状态或样例时逐步说明，其他步骤照常取证。 [4]准备一条可启用及一条可禁用的记录；启停确认文案和风险语义已确认。 | D10: [1]打开禁用确认，阅读图标、标题、对象名称和影响说明。 [2]点击“取消”，返回列表查看当前记录。 [3]打开启用确认，对比标题、影响说明及确认按钮。 [4]关闭确认，再次打开同一动作。 | E10: [1]采用批准的风险语义；对象和影响具体可读，不混用不可恢复删除文案。 [2]确认关闭；页面状态标签与按钮未提前改变。 [3]启用与禁用的动作语义明确不同，确认对象准确；按钮名称能说明将执行的动作。 [4]再次打开时为当前对象和当前动作，不残留上一次另一动作的文案。 | F10: P0 | G10: 【设计依据】场景法-风险确认和取消 【测试类型】interaction 【追溯信息】用例编号：UI-W2-05-1；原用例：W2-05-1；排期序号5/原表行9 【知识库依据】RV09/规范7.3 【准入状态】按实际交付入口介入；专项缺口逐步记录 【执行范围】检查界面呈现、交互路径与恢复；业务规则正确性沿用功能测试。 【来源边界】业务PRD/专项设计稿未读取；排期“PRD”仅为来源标签。本条为候选用例；通用规范明确要求可先查，业务专项判据须与相应基线核对。 【待补判据】启停动作及风险文案/语义色（RV09待确认）、引用限制及冲突响应中的具体提示和恢复动作。未明确的子步骤记受阻。 【审查方式】用例文本及来源自行复核；本轮页面未执行，执行结果另填。 【本周安排】今天输出UI规范审查及修改清单；本周对实际交付页面全面介入UI与交互。异常/边界缺样例逐步受阻，功能验证按原分工。 | H10: 未执行 | K10: 未执行 | L10: 原候选步骤未完整重跑；本次已交付M1补测见下方UI-M1-001–025，不替代本条。 | M10: W2-dev-20261014-5c6bc530 | N10: 未执行 | O10: 本轮聚焦主数据相关31条；本条未复核，K-M旧轮次记录保留。 | P10: W2-master-20261014-fd786de-8cdf1453 本轮未涉及 | Q10: 未重跑；不产生新通过/失败结论。
A11: 服务单元被引用或并发改变时能恢复操作 | B11: /SN318/W2/服务单元/禁用编排/启用 与产品引用关系/exception | C11: [1]使用具备“服务单元”页面权限的测试账号，进入本批提测环境。 [2]实际业务页面已交付且入口可访问；通用规范已有明确要求的步骤可先走查。 [3]记录Build、URL、角色及样例；专项PRD/设计稿未补齐仅阻塞依赖其判据的步骤。缺入口时整条受阻；缺状态或样例时逐步说明，其他步骤照常取证。 [4]提供被引用、状态已改变及并发冲突的前端响应样例；不验证引用判定算法。 | D11: [1]打开启停确认，选用“被引用不可操作”样例并确认。 [2]关闭错误提示，切换“状态已被其他用户改变”样例再次操作。 [3]切换并发冲突样例，检查确认按钮结束状态。 [4]返回列表并重新打开详情或确认。 | E11: [1]出现明确的引用限制原因；未成功前列表不显示为已完成目标状态。 [2]提示当前对象状态已变化，并提供刷新/返回等批准的后续动作。 [3]冲突说明可理解；loading结束，按钮可按批准路径重新操作。 [4]对象和状态呈现一致，没有遗留遮罩、失效按钮或错误成功提示。 | F11: P0 | G11: 【设计依据】错误推测法-失败原因和状态恢复 【测试类型】exception 【追溯信息】用例编号：UI-W2-05-2；原用例：W2-05-2；排期序号5/原表行9 【知识库依据】阶段共识19/PRD业务规则另测 【准入状态】按实际交付入口介入；专项缺口逐步记录 【执行范围】检查界面呈现、交互路径与恢复；业务规则正确性沿用功能测试。 【来源边界】业务PRD/专项设计稿未读取；排期“PRD”仅为来源标签。本条为候选用例；通用规范明确要求可先查，业务专项判据须与相应基线核对。 【待补判据】启停动作及风险文案/语义色（RV09待确认）、引用限制及冲突响应中的具体提示和恢复动作。未明确的子步骤记受阻。 【异常取证】执行前记录具体响应、切换入口及数据来源；无法从页面触发的异常步骤记受阻，不用直接展示页替代。 【审查方式】用例文本及来源自行复核；本轮页面未执行，执行结果另填。 【本周安排】今天输出UI规范审查及修改清单；本周对实际交付页面全面介入UI与交互。异常/边界缺样例逐步受阻，功能验证按原分工。 | H11: 未执行 | K11: 未执行 | L11: 原候选步骤未完整重跑；本次已交付M1补测见下方UI-M1-001–025，不替代本条。 | M11: W2-dev-20261014-5c6bc530 | N11: 未执行 | O11: 本轮聚焦主数据相关31条；本条未复核，K-M旧轮次记录保留。 | P11: W2-master-20261014-fd786de-8cdf1453 本轮未涉及 | Q11: 未重跑；不产生新通过/失败结论。
A12: 服务组合列表与详情入口的层级一致 | B12: /SN318/W2/服务组合/服务组合列表页/UI | C12: [1]使用具备“服务组合”页面权限的测试账号，进入本批提测环境。 [2]实际业务页面已交付且入口可访问；通用规范已有明确要求的步骤可先走查。 [3]记录Build、URL、角色及样例；专项PRD/设计稿未补齐仅阻塞依赖其判据的步骤。缺入口时整条受阻；缺状态或样例时逐步说明，其他步骤照常取证。 [4]服务组合列表存在有效记录；筛选字段及详情承载已批准。 | D12: [1]进入服务组合列表，查看页头、筛选区、状态及主操作。 [2]点击一条记录的详情链接。 [3]返回列表，切换状态筛选并观察刷新。 | E12: [1]布局层级与同类列表一致；仅显示实际需要的筛选字段，状态有文字含义。 [2]详情入口可发现且可点击；打开所选服务组合，标题和对象标识一致。 [3]返回和筛选操作有可见反馈，当前菜单及列表工具栏归属未发生错位。 | F12: P0 | G12: 【设计依据】场景法-列表和详情导航 【测试类型】UI 【追溯信息】用例编号：UI-W2-07-1；原用例：W2-07-1；排期序号7/原表行11 【知识库依据】RV12-RV19 【准入状态】按实际交付入口介入；专项缺口逐步记录 【执行范围】检查界面呈现、交互路径与恢复；业务规则正确性沿用功能测试。 【来源边界】业务PRD/专项设计稿未读取；排期“PRD”仅为来源标签。本条为候选用例；通用规范明确要求可先查，业务专项判据须与相应基线核对。 【待补判据】详情入口/承载、每页N、0条和空末页时分页恢复规则、实际空态文案。未明确的子步骤记受阻。 【审查方式】用例文本及来源自行复核；本轮页面未执行，执行结果另填。 【本周安排】今天输出UI规范审查及修改清单；本周对实际交付页面全面介入UI与交互。异常/边界缺样例逐步受阻，功能验证按原分工。 | H12: 未执行 | K12: 未执行 | L12: 原候选步骤未完整重跑；本次已交付M1补测见下方UI-M1-001–025，不替代本条。 | M12: W2-dev-20261014-5c6bc530 | N12: 未执行 | O12: 本轮聚焦主数据相关31条；本条未复核，K-M旧轮次记录保留。 | P12: W2-master-20261014-fd786de-8cdf1453 本轮未涉及 | Q12: 未重跑；不产生新通过/失败结论。
A13: 服务组合零条及末页数据的分页展示正确 | B13: /SN318/W2/服务组合/服务组合列表页/boundary | C13: [1]使用具备“服务组合”页面权限的测试账号，进入本批提测环境。 [2]实际业务页面已交付且入口可访问；通用规范已有明确要求的步骤可先走查。 [3]记录Build、URL、角色及样例；专项PRD/设计稿未补齐仅阻塞依赖其判据的步骤。缺入口时整条受阻；缺状态或样例时逐步说明，其他步骤照常取证。 [4]批准每页条数为N；提供0、1、N、N+1条及末页不足N条的前端数据样例。 | D13: [1]切换0条样例，并分别展示首次无数据与筛选无结果。 [2]依次切换1、N及N+1条样例，查看总数与页码。 [3]进入末页，查看行操作与分页条。 [4]通过前端样例使当前末页变为空，观察页码恢复。 | E13: [1]两种空态使用相应说明和操作引导；不能统一显示为相同原因。 [2]总数对应样例；N+1条可进入第二页，末页条数与总数可对应。 [3]末页记录不足N条时布局正常，行操作及分页入口仍可点击。 [4]不会停在无法返回的空末页；按批准策略退回可用页，页码与总数一致。 | F13: P0 | G13: 【设计依据】边界值分析-0/1/N/N+1条 【测试类型】boundary 【追溯信息】用例编号：UI-W2-07-2；原用例：W2-07-2；排期序号7/原表行11 【知识库依据】RV15/规范7.2 【准入状态】按实际交付入口介入；专项缺口逐步记录 【执行范围】检查界面呈现、交互路径与恢复；业务规则正确性沿用功能测试。 【来源边界】业务PRD/专项设计稿未读取；排期“PRD”仅为来源标签。本条为候选用例；通用规范明确要求可先查，业务专项判据须与相应基线核对。 【待补判据】详情入口/承载、每页N、0条和空末页时分页恢复规则、实际空态文案。未明确的子步骤记受阻。 【审查方式】用例文本及来源自行复核；本轮页面未执行，执行结果另填。 【本周安排】今天输出UI规范审查及修改清单；本周对实际交付页面全面介入UI与交互。异常/边界缺样例逐步受阻，功能验证按原分工。 | H13: 未执行 | K13: 未执行 | L13: 原候选步骤未完整重跑；本次已交付M1补测见下方UI-M1-001–025，不替代本条。 | M13: W2-dev-20261014-5c6bc530 | N13: 未执行 | O13: 本轮聚焦主数据相关31条；本条未复核，K-M旧轮次记录保留。 | P13: W2-master-20261014-fd786de-8cdf1453 本轮未涉及 | Q13: 未重跑；不产生新通过/失败结论。
... A102: 基础配置汇率公共视觉规范 | B102: /SN318/W2/已交付M1补测 | C102: 本地dev + useMockAuth/useMockData，demo角色，1440×900/100%；只判前端Mock表现。仅汇率实际对象量测，不替代全部资源字段专项 | D102: [1]量测查询按钮 [2]量测表格正文与数字 [3]量测卡片 | E102: [1]按钮圆角8px [2]正文#4B5564，数字右对齐，操作左对齐 [3]圆角12px、padding24px | F102: P1 | G102: 【用例编号】UI-M1-025 【依据】V1.2 3.1/5.1/5.8/5.9 【范围】仅汇率实际对象量测，不替代全部资源字段专项 【工作包】W2-51 | H102: 未执行（新增记录无历史） | K102: 不通过 | L102: [1]【不通过】32px高、圆角2px。 证据：B46-master-common-metrics [2]【不通过】正文#1A2130、ratio内层左对齐、操作居中。 证据：B46-master-common-metrics [3]【通过】两张公共卡片12px/24px。 证据：B46-master-common-metrics | M102: W2-dev-20261014-5c6bc530 | N102: 不通过 | O102: [1]【不通过】查询按钮32px高、圆角2px，预期8px。 证据：C03-rate-visual [2]【不通过】正文#1A2130；ratio 7.1234的实际内层为left，操作内层居中、间距4px。预期正文#4B5564、数字右对齐、操作左对齐。 证据：C03-rate-visual, C03-rate-metrics [3]【通过】实际表格卡片.by-card--default为圆角12px、padding24px；量测真实卡片祖先，未用表格容器8px替代。 证据：C09-cards-and-tabs | P102: W2-master-20261014-fd786de-8cdf1453 1440×900 / 100% / demo / dev Mock | Q102: 不通过 → 不通过；只比较记录轮次，不当作源码修复证明。

Sheet 通用模板UI与交互用例
A1: 用例名称 | B1: 所属模块 | C1: 前置条件 | D1: 步骤描述 | E1: 预期结果 | F1: 用例等级 | G1: 备注 | H1: 执行状态 | I1: 实际结果/证据 | J1: 人工二次复核 | K1: 本次执行状态（2026-10-14） | L1: 本次实际结果/证据（原H/I/J保留） | M1: 本次Build/覆盖
A2: 列表标题按钮和卡片尺寸符合通用基线 | B2: /pcs-front/通用模板/视觉规范/标题与容器 | C2: [1]本地通用模板 http://127.0.0.1:5173/home 可访问；浏览器缩放100%。 [2]将视口设置为1440×900，进入示例管理的列表页。 | D2: [1]查看页头标题，通过浏览器计算样式读取字号和字重。 [2]读取默认按钮高度及圆角。 [3]读取主卡片圆角及内边距。 | E2: [1]H1字号20px、字重500；页面只有一个主要标题，标题含义与当前列表一致。 [2]默认按钮高32px、圆角8px，文字未被裁切，主次按钮语义清楚。 [3]卡片圆角12px、内边距24px；内容和边缘保留一致间距。 | F2: P2 | G2: 【设计依据】视觉规范/标题与容器 【测试类型】UI 【追溯信息】用例编号：UI-TPL-001；原检查：T01；原设计修改项：无 【知识库依据】3.2 s4NgFa、3.4 jYqjvY、5.1 Jhut4D、5.9 O6GcDy 【准入状态】已确认差异，待修改复测。 【执行说明】2026-10-13实测见右侧；受阻项逐步保留原因。 【审查方式】浏览器实际操作、截图及只读DOM量测；Mock源码仅用于确认样例限制。 【全面复核】维持不通过，按钮2px圆角由既有量测确认。 【本次清单】M01 | H2: 不通过 | I2: 2026-10-14复核｜本地dev/Mock｜/demo/list [1]【通过】唯一H1“运单管理”，20px/500。 [2]【不通过】查询按钮32px高、圆角2px，规范8px。 [3]【通过】筛选及表格卡片圆角12px、padding24px。 证据：V02、A01；见配套复核证据.html。 | J2: 不通过 | K2: 不通过 | L2: [1]【通过】唯一H1运单管理，20px/500。 证据：T01-list-baseline [2]【不通过】查询32px高、圆角2px，要求8px。 证据：T01-list-baseline [3]【受阻】本次未完成该分支判定；历史结果另保留。 缺条件：本轮列表外层卡片未独立量测；历史值不能代替本次 证据：T13-container-metrics | M2: W2-dev-20261014-5c6bc530 本地dev/Mock；不覆盖真实接口；逐步受阻见左列
A3: 标准页头高度和面包屑位置符合规范 | B3: /pcs-front/通用模板/视觉规范/页头 | C3: [1]本地通用模板 http://127.0.0.1:5173/home 可访问；浏览器缩放100%。 [2]1440×900视口；列表使用标准型页头，包含面包屑、主标题和操作区。 | D3: [1]进入列表，确认页头为标准型。 [2]读取标准页头及面包屑的实际边界高度。 [3]查看页头右侧操作与标题底部的对齐。 | E3: [1]页头具有标准型规定的组成，不将完整型或简洁型误作为本用例对象。 [2]标准页头总高94px，面包屑高18px；标题行高及间距符合4.2。 [3]无副标题时操作区与主标题底部对齐；没有额外空隙造成页头增高。 | F3: P2 | G3: 【设计依据】视觉规范/页头 【测试类型】UI 【追溯信息】用例编号：UI-TPL-002；原检查：T02；原设计修改项：F02 【知识库依据】4.2 FFO2Ix、0rCax8 【准入状态】已确认差异，待修改复测。 【执行说明】2026-10-13实测见右侧；受阻项逐步保留原因。 【审查方式】浏览器实际操作、截图及只读DOM量测；Mock源码仅用于确认样例限制。 【全面复核】维持不通过；修正来源定位为4.2。 【本次清单】M02 | H3: 不通过 | I3: 2026-10-14复核｜本地dev/Mock｜/demo/list [1]【通过】标准型页头，面包屑、标题、操作齐全。 [2]【不通过】页头97px、面包屑18px，标准页头规范94px。 [3]【通过】标题及右侧按钮底部均y=133，底部对齐。 证据：V02、V76、A01；见配套复核证据.html。 | J3: 不通过 | K3: 不通过 | L3: [1]【通过】标准页头含面包屑、标题和操作区。 证据：T01-list-baseline [2]【不通过】标准页头97px；面包屑18px。要求94px。 证据：T01-list-baseline、T13-container-metrics [3]【通过】标题与操作区底部对齐，截图可见。 证据：T01-list-baseline | M3: W2-dev-20261014-5c6bc530 本地dev/Mock；不覆盖真实接口；逐步受阻见左列
A4: 列表操作列左对齐且文字按钮间距16px | B4: /pcs-front/通用模板/视觉规范/操作列 | C4: [1]本地通用模板 http://127.0.0.1:5173/home 可访问；浏览器缩放100%。 [2]1440×900视口；列表首行包含“详情”“跟踪”等文字操作。 | D4: [1]查看首行操作列，读取单元格内层对齐方式及按钮间距。 [2]将表格横向滚动到最右侧。 [3]将视口调整为1280和1024宽，重复查看行操作。 | E4: [1]操作内容左对齐，文字按钮间距16px；以实际内容容器为准。 [2]操作列固定在最右侧，文字及按钮不被裁切，与主体列不重叠。 [3]操作仍完整可达，调整列宽后未产生固定列重叠或页面级横向滚动。 | F4: P2 | G4: 【设计依据】视觉规范/操作列 【测试类型】UI 【追溯信息】用例编号：UI-TPL-003；原检查：T03；原设计修改项：F01 【知识库依据】5.8 tkqkxw、IOfbnI；4.5.2 lfEtqB 【准入状态】已确认差异，待修改复测。 【执行说明】2026-10-13实测见右侧；受阻项逐步保留原因。 【审查方式】浏览器实际操作、截图及只读DOM量测；Mock源码仅用于确认样例限制。 【全面复核】维持不通过：居中/8px，固定列已通过。 【本次清单】M03 | H4: 不通过 | I4: 2026-10-14复核｜本地dev/Mock｜/demo/list [1]【不通过】操作内层居中，按钮gap8px；规范左对齐、16px。 [2]【通过】1024宽横滚至157px，操作列sticky/right0。 [3]【通过】1280/1024无根级横向溢出；仅表格内部横滚。 证据：V02、V09、V10、V12。截图、DOM及量测见配套复核证据.html。 | J4: 不通过 | K4: 不通过 | L4: [1]【不通过】实际内层居中、gap8px，要求左对齐/16px。 证据：T01-list-baseline、T13-container-metrics [2]【受阻】本次未完成该分支判定；历史结果另保留。 缺条件：本轮横滚尝试scrollLeft仍为0，不能当作横滚完成 证据：T16-tablet-horizontal [3]【通过】1280/1024无根级横向溢出；固定行操作在视口内。 证据：T14-list-1280、T15-list-1024、T16-tablet-horizontal | M4: W2-dev-20261014-5c6bc530 本地dev/Mock；不覆盖真实接口；逐步受阻见左列
A5: 普通表格正文颜色与标题及语义色区分 | B5: /pcs-front/通用模板/视觉规范/正文颜色 | C5: [1]本地通用模板 http://127.0.0.1:5173/home 可访问；浏览器缩放100%。 [2]列表含普通目的地、重量、日期文本，以及链接和状态标签。 | D5: [1]读取目的地、重量和日期实际显示文本的计算颜色。 [2]查看标题、业务链接和状态Tag。 [3]选中或悬停一行后再次查看可读性。 | E5: [1]普通正文使用color-text-body，即#4B5564。 [2]标题、链接及语义Tag使用各自规定颜色，不被普通正文色统一覆盖。 [3]背景变化后文字仍清楚；没有因整行覆盖色导致状态或链接含义丢失。 | F5: P2 | G5: 【设计依据】视觉规范/正文颜色 【测试类型】UI 【追溯信息】用例编号：UI-TPL-004；原检查：T04；原设计修改项：F03 【知识库依据】3.1 hezLMm；5.8 IOfbnI 【准入状态】已确认差异，待修改复测。 【执行说明】2026-10-13实测见右侧；受阻项逐步保留原因。 【审查方式】浏览器实际操作、截图及只读DOM量测；Mock源码仅用于确认样例限制。 【全面复核】维持不通过。 【本次清单】M04 | H5: 不通过 | I5: 2026-10-14实测复核｜本地dev/Mock｜/demo/list [1]【不通过】目的地/重量/日期正文#1A2130，规范#4B5564。 [2]【不通过】链接#165DFF，现行3.1规定#046EFC；Tag各色未完整核对。 [3]【通过】选中/hover仍保留链接与标签含义（首轮V06/V77）。 证据：V02、V06、V77、A01、A03、A30；见配套复核证据.html。 | K5: 不通过 | L5: [1]【不通过】目的地/重量/日期普通文本#1A2130，要求#4B5564。 证据：T01-list-baseline [2]【不通过】运单链接#165DFF，规范Brand Blue为#046EFC；Tag未全色核对。 证据：T01-list-baseline [3]【受阻】本次未完成该分支判定；历史结果另保留。 缺条件：本轮未分别复测hover/选中下全部语义色；仅选中背景量测 证据：T06-selected | M5: W2-dev-20261014-5c6bc530 本地dev/Mock；不覆盖真实接口；逐步受阻见左列
A6: 列表行高和数字内层对齐符合规范 | B6: /pcs-front/通用模板/视觉规范/表格行列 | C6: [1]本地通用模板 http://127.0.0.1:5173/home 可访问；浏览器缩放100%。 [2]列表有至少2行记录，包含重量/运费及状态。 | D6: [1]量测首两行数据行，读取表头背景、字重和行底线。 [2]读取重量和运费实际文本容器的对齐方式、字号和字重。 [3]查看名称、日期、状态和操作列，再悬停未选中行。 | E6: [1]数据行高48px；表头背景#F7F7F7、字重500；数据行仅底部1px solid #EBEBEB分割线。 [2]数字右对齐，普通正文14px/400；以实际文本容器为准，不能仅凭外层td样式判断。 [3]名称、日期、状态、操作左对齐；未选中行hover背景#EBF3FD；文字、标签及按钮不重叠。 | F6: P2 | G6: 【设计依据】视觉规范/表格行列 【测试类型】UI 【追溯信息】用例编号：UI-TPL-005；原检查：T05；原设计修改项：无 【知识库依据】5.8 IOfbnI、tkqkxw、hiuQkw；3.2 s4NgFa 【准入状态】已确认差异，待修改复测。 【执行说明】2026-10-13实测见右侧；受阻项逐步保留原因。 【审查方式】浏览器实际操作、截图及只读DOM量测；Mock源码仅用于确认样例限制。 【全面复核】原通过漏计操作列居中，按003同一证据修正为不通过。 【本次清单】M03 | H6: 不通过 | I6: 2026-10-14复核｜本地dev/Mock｜/demo/list [1]【通过】前两行48px，表头#F7F7F7/500，数据行底线1px #EBEBEB。 [2]【通过】重量/运费内层右对齐，14px/400。 [3]【不通过】操作仍居中；其他文字列左对齐，hover底色#EBF3FD。 证据：V02、V77。截图、DOM及量测见配套复核证据.html。 | K6: 不通过 | L6: [1]【受阻】本次未完成该分支判定；历史结果另保留。 缺条件：行底线未独立量测；已确认行高48/表头#F7F7F7/500 证据：T01-list-baseline [2]【通过】重量/运费实际内层右对齐，14px/400。 证据：T01-list-baseline [3]【不通过】操作列实际居中；名称等左对齐。hover背景本轮未量测。 证据：T01-list-baseline | M6: W2-dev-20261014-5c6bc530 本地dev/Mock；不覆盖真实接口；逐步受阻见左列
A7: 列表搜索无结果时保留条件并提供恢复引导 | B7: /pcs-front/通用模板/场景法/空结果 | C7: [1]本地通用模板 http://127.0.0.1:5173/home 可访问；浏览器缩放100%。 [2]列表正常有数据；准备不存在的运单号“UI-NO-MATCH-20261013”。 | D7: [1]在运单号输入框填写上述值，点击查询。 [2]查看无结果区域和筛选区。 [3]查找清空/重置入口。 | E7: [1]查询有反馈，结果为0条，不继续展示旧查询结果。 [2]显示未找到相关结果及调整筛选说明；筛选输入保留。 [3]恢复入口清楚可达，用户能知道如何离开无结果状态。 | F7: P2 | G7: 【设计依据】场景法/空结果 【测试类型】interaction 【追溯信息】用例编号：UI-TPL-006；原检查：T06；原设计修改项：无 【知识库依据】7.2 2xUUpH 【准入状态】本条修订后的步骤已覆盖。 【执行说明】2026-10-13实测见右侧；受阻项逐步保留原因。 【审查方式】浏览器实际操作、截图及只读DOM量测；Mock源码仅用于确认样例限制。 【全面复核】维持通过；文案换行/合理补充不按逐字错误处理。 | H7: 通过 | I7: 2026-10-14复核｜本地dev/Mock｜/demo/list [1]【通过】查询UI-NO-MATCH-20261014，完成态0条、旧数据退出。 [2]【通过】“未找到相关结果 / 请调整筛选条件后重试”，输入保留。 [3]【通过】重置仍可达并能恢复列表。 证据：V03、V04、A07、A08；见配套复核证据.html。 | K7: 通过 | L7: [1]【通过】不存在的NO_UI_20261014查询后0条，旧结果退出。 证据：T03-query-empty [2]【通过】未找到相关结果/请调整筛选条件后重试，输入保留。 证据：T03-query-empty [3]【通过】重置可达，能退出空结果。 证据：T04-reset-restored | M7: W2-dev-20261014-5c6bc530 本地dev/Mock；不覆盖真实接口；逐步受阻见左列
A8: 重置筛选后退出无结果态 | B8: /pcs-front/通用模板/状态转换/筛选重置 | C8: [1]本地通用模板 http://127.0.0.1:5173/home 可访问；浏览器缩放100%。 [2]先按UI-TPL-006进入无结果状态；记录模板初始筛选值。 | D8: [1]点击重置按钮，查看筛选控件。 [2]查看列表刷新结束后的内容与总数。 [3]再次填写有效条件查询。 | E8: [1]筛选恢复模板定义的初始值，不残留无结果测试词。 [2]退出无结果态并恢复当前Mock列表，页码与数据相互对应。 [3]筛选控件仍可操作，上一空态不覆盖新结果。 | F8: P2 | G8: 【设计依据】状态转换/筛选重置 【测试类型】interaction 【追溯信息】用例编号：UI-TPL-007；原检查：T07；原设计修改项：无 【知识库依据】7.2 2xUUpH；2.1一致可预期 【准入状态】本条修订后的步骤已覆盖。 【执行说明】2026-10-13实测见右侧；受阻项逐步保留原因。 【审查方式】浏览器实际操作、截图及只读DOM量测；Mock源码仅用于确认样例限制。 【全面复核】维持通过；未宣称筛选持久化或数据业务正确性。 | H8: 通过 | I8: 2026-10-14复核｜本地dev/Mock｜/demo/list [1]【通过】重置清空运单号，状态/渠道为全部，日期空。 [2]【通过】恢复86条及5页。 [3]【通过】再次查询BY10000001得到1条，旧空态不残留。 证据：V04、V05、A08、A09；见配套复核证据.html。 | K8: 通过 | L8: [1]【通过】重置清空测试词、状态/渠道恢复默认、日期为空。 证据：T04-reset-restored [2]【通过】恢复86条、页码和内容对应。 证据：T04-reset-restored [3]【通过】再次查询BY10000001得到1条，旧空态退出。 证据：T05-valid-filter | M8: W2-dev-20261014-5c6bc530 本地dev/Mock；不覆盖真实接口；逐步受阻见左列
A9: 单行选中后批量栏出现且取消可恢复默认工具栏 | B9: /pcs-front/通用模板/状态转换/批量栏 | C9: [1]本地通用模板 http://127.0.0.1:5173/home 可访问；浏览器缩放100%。 [2]列表有至少一条记录且初始未选中。 | D9: [1]勾选首行，观察表格顶部。 [2]查看批量操作与默认刷新/导出区域。 [3]点击取消选择。 | E9: [1]显示已选择1项及批量操作栏，位置属于当前表格。 [2]批量模式和默认模式区分清楚，不出现两套工具栏重叠。 [3]勾选清空，批量栏消失，恢复默认工具栏。 | F9: P2 | G9: 【设计依据】状态转换/批量栏 【测试类型】interaction 【追溯信息】用例编号：UI-TPL-008；原检查：T08；原设计修改项：无 【知识库依据】5.8 KJawbG 【准入状态】本条修订后的步骤已覆盖。 【执行说明】2026-10-13实测见右侧；受阻项逐步保留原因。 【审查方式】浏览器实际操作、截图及只读DOM量测；Mock源码仅用于确认样例限制。 【全面复核】维持通过。 | H9: 通过 | I9: 2026-10-14复核｜本地dev/Mock｜/demo/list [1]【通过】勾BY10000001，显示已选择1项及批量栏。 [2]【通过】替换默认刷新区，无两套工具栏重叠。 [3]【通过】取消选择后勾选、批量栏清空，默认工具栏恢复。 证据：V06、V11、A10、A16；见配套复核证据.html。 | K9: 通过 | L9: [1]【通过】首行选择后显示已选择1项。 证据：T06-selected [2]【通过】批量栏替代默认操作栏，无重叠。 证据：T06-selected [3]【通过】取消后选择清空、默认栏恢复。 证据：T08-selection-cleared | M9: W2-dev-20261014-5c6bc530 本地dev/Mock；不覆盖真实接口；逐步受阻见左列
A10: 选中底色覆盖左右固定列和主体单元格 | B10: /pcs-front/通用模板/视觉规范/选中行 | C10: [1]本地通用模板 http://127.0.0.1:5173/home 可访问；浏览器缩放100%。 [2]列表有左右固定列；1440×900视口。 | D10: [1]勾选首行并读取该行全部单元格背景。 [2]水平滚动表格，查看固定列边界。 [3]取消该行选择。 | E10: [1]主体及左右固定单元格背景均为#D1E4FB。 [2]选中底色连续，未出现固定列白底断层或文字被盖住。 [3]所有列退出选中背景，未残留局部选中色。 | F10: P2 | G10: 【设计依据】视觉规范/选中行 【测试类型】UI 【追溯信息】用例编号：UI-TPL-009；原检查：T09；原设计修改项：无 【知识库依据】5.8 hiuQkw、KJawbG；4.5.2 lfEtqB 【准入状态】本条修订后的步骤已覆盖。 【执行说明】2026-10-13实测见右侧；受阻项逐步保留原因。 【审查方式】浏览器实际操作、截图及只读DOM量测；Mock源码仅用于确认样例限制。 【全面复核】维持通过。 | H10: 通过 | I10: 2026-10-14复核｜本地dev/Mock｜/demo/list [1]【通过】选中行9个单元格均#D1E4FB。 [2]【通过】1024宽横滚157px，左右固定列与主体底色连续。 [3]【通过】取消后9列恢复白底。 证据：V06、V10、V11、A10、A16；见配套复核证据.html。 | K10: 受阻 | L10: [1]【通过】全部主体/左右固定td均rgb(209,228,251)=#D1E4FB。 证据：T06-selected [2]【受阻】本次未完成该分支判定；历史结果另保留。 缺条件：水平滚动未完成；不引用历史横滚作为本轮通过 证据：T16-tablet-horizontal [3]【通过】取消后选择栏消失。 证据：T08-selection-cleared | M10: W2-dev-20261014-5c6bc530 本地dev/Mock；不覆盖真实接口；逐步受阻见左列
A11: 批量删除确认中的对象数量和取消语义明确 | B11: /pcs-front/通用模板/场景法/危险确认 | C11: [1]本地通用模板 http://127.0.0.1:5173/home 可访问；浏览器缩放100%。 [2]列表选择1条；本用例只打开确认并取消，不执行删除。 | D11: [1]点击批量删除，阅读确认内容。 [2]查看取消和确认删除按钮。 [3]点击取消，查看列表记录及状态。 | E11: [1]正确说明将删除选中的1项，包含不可恢复风险及明确对象范围。 [2]取消在左，确认删除在右；危险动作名称清楚。 [3]确认关闭，原记录仍在；没有删除成功提示或提前移除行。 | F11: P2 | G11: 【设计依据】场景法/危险确认 【测试类型】interaction 【追溯信息】用例编号：UI-TPL-010；原检查：T10；原设计修改项：无 【知识库依据】5.10 WJHXDG、t5GXhY；7.3 7j2jDv；8.3 GF7nRn 【准入状态】批量确认弹窗自身宽度等未量测，若扩展尺寸验收需补取证。 【执行说明】2026-10-13实测见右侧；受阻项逐步保留原因。 【审查方式】浏览器实际操作、截图及只读DOM量测；Mock源码仅用于确认样例限制。 【全面复核】维持本条交互通过；未量测的批量确认尺寸不借用组件页结果。 | H11: 通过 | I11: 2026-10-14复核｜本地dev/Mock｜/demo/list [1]【通过】确认说明选中1项及“删除后不可恢复”。 [2]【通过】取消在左、确认删除在右。 [3]【通过】仅点击取消，BY10000001和86条仍在，无删除成功提示。 证据：V07、V08、A11、A12、A16；见配套复核证据.html。 | K11: 通过 | L11: [1]【通过】明确删除1项及不可恢复说明。 证据：T07-delete-confirm [2]【通过】取消在左、确认删除在右。 证据：T07-delete-confirm [3]【通过】取消后原首行仍在，未执行删除。 证据：T08-selection-cleared | M11: W2-dev-20261014-5c6bc530 本地dev/Mock；不覆盖真实接口；逐步受阻见左列
A12: 详情抽屉的分组关闭和原列表上下文清楚 | B12: /pcs-front/通用模板/场景法/详情抽屉 | C12: [1]本地通用模板 http://127.0.0.1:5173/home 可访问；浏览器缩放100%。 [2]列表有可查看详情的运单；记录筛选和对象；按5.11记录默认480px或多内容宽抽屉640px的实际选型；准备可保持详情加载的样例。 | D12: [1]点击详情，量测抽屉宽度、高度、标题、内边距和遮罩。 [2]查看对象和字段分组，滚动内容至末尾，查看标题与底部操作。 [3]从底部关闭、重新打开后从顶部关闭，再重新打开并点击遮罩。 [4]用受控样例延迟详情加载，尝试顶部关闭。 | E12: [1]抽屉贴右并撑满视口；默认宽度480px，内容较多的宽抽屉640px；标题16px/500、内边距24px、遮罩rgba(0,0,0,0.45)。 [2]展示所选对象；内容区独立滚动，标题和有操作的底栏保持固定，底栏右对齐；字段不被底栏遮挡。 [3]关闭入口及遮罩点击均可关闭；回到原列表并保留原筛选，无残留遮罩或对象串用。 [4]加载只在内容区显示骨架或Spin；标题、关闭按钮仍可操作，关闭后不被迟到响应重新弹开。 | F12: P2 | G12: 【设计依据】场景法/详情抽屉 【测试类型】interaction 【追溯信息】用例编号：UI-TPL-011；原检查：T11；原设计修改项：无 【知识库依据】5.11 7nFRad、IpxRU6；6.2 qif9bA 【准入状态】当前固定300ms Mock可进入加载并关闭，已完成本条本地验证。 【执行说明】2026-10-13实测见右侧；受阻项逐步保留原因。 【审查方式】浏览器实际操作、截图及只读DOM量测；Mock源码仅用于确认样例限制。 【全面复核】2026-10-14续测：末尾滚动/三种关闭/骨架及加载中关闭、迟到响应均已取证，改为通过。 【本次清单】B011 | H12: 通过 | I12: 2026-10-14受阻核实｜本地dev/Mock｜/demo/list [1]【通过】宽抽屉640×900，标题16/500、遮罩0.45；实际内容.drawer-detail内边距24px，包装层为0。 [2]【通过】滚至末尾scrollTop158，标题/底栏固定，备注bottom786在底栏top835上方。 [3]【通过】底部、顶部、遮罩关闭均保留BY10000021筛选和1条记录。 [4]【通过】默认300ms Mock中内容骨架可见；加载中顶部关闭，迟到响应不重开。 范围：无。本条在当前固定300ms前端Mock范围完成；未扩展为真实后端验收。 本轮证据：B02、B03、B04、B05、B06、B07、B08、B09、B43、B44、B45、B46；见配套报告。 | K12: 受阻 | L12: [1]【受阻】本次未完成该分支判定；历史结果另保留。 缺条件：已量测宽高/标题/padding，但遮罩rgba本轮未复测 证据：T18-drawer-loaded [2]【通过】所选对象信息正确；768视口内容scrollTop98，已到末尾，底栏固定831–900。 证据：T43-drawer-tablet [3]【受阻】本次未完成该分支判定；历史结果另保留。 缺条件：仅底部关闭已完成；顶部/遮罩路径本轮未全部重跑 证据：T44-final-list [4]【受阻】本次未完成该分支判定；历史结果另保留。 缺条件：加载时顶部关闭定位发生动画/节点替换，未完成点击与迟到响应验证 证据：T17-drawer-loading、T19-drawer-current | M12: W2-dev-20261014-5c6bc530 本地dev/Mock；不覆盖真实接口；逐步受阻见左列
A13: 新建表单必填错误显示在对应字段下并可纠正 | B13: /pcs-front/通用模板/等价类划分/必填错误 | C13: [1]本地通用模板 http://127.0.0.1:5173/home 可访问；浏览器缩放100%。 [2]进入新建运单，保留模板合法默认值；目的地、日期、收件人、电话等可录入必填项未填，重量为默认0以触发错误。本条只检校验呈现及纠错，不检全部必填业务组合。 | D13: [1]点击保存，查看表单反馈。 [2]逐个查看有错误的字段及相邻控件。 [3]修正其中一个必填字段，重新触发校验。 | E13: [1]停留在表单，对未填必填项显示字段下方红色提示，不弹额外错误确认框。 [2]错误说明与字段对应，不遮挡标签、下一字段或底部操作。 [3]该字段旧错误清除；其他仍未填写的字段继续提示，不误清空已有输入。 | F13: P2 | G13: 【设计依据】等价类划分/必填错误 【测试类型】interaction 【追溯信息】用例编号：UI-TPL-012；原检查：T12；原设计修改项：无 【知识库依据】5.7 UXf6DG；7.3 7j2jDv 【准入状态】业务类型为空组合未构造，留给功能字段校验；不宣称全部必填组合通过。 【执行说明】2026-10-13实测见右侧；受阻项逐步保留原因。 【审查方式】浏览器实际操作、截图及只读DOM量测；Mock源码仅用于确认样例限制。 【全面复核】前置改为保留合法默认值、清空可录入必填字段；已有3步UI证据通过。 | H13: 通过 | I13: 2026-10-14复核｜本地dev/Mock｜/demo/list/form [1]【通过】保留默认快递及金额0；空保存提示目的地、日期、收件人、电话及重量错误。 [2]【通过】字段下就地红色提示，无额外错误确认框。 [3]【通过】修正目的地后旧错误清除，其余错误仍在，输入保留。 边界：未构造业务类型清空等全部业务组合。 证据：V21、V22、A17、A18；见配套复核证据.html。 | K13: 通过 | L13: [1]【通过】空保存保持表单，字段下就地错误，无额外错误弹窗。 证据：T23-form-required [2]【通过】错误与对应字段相邻，不盖住控件/底栏。 证据：T23-form-required、T27-form-tablet [3]【通过】纠正目的地后其错误消失，其他必填错误保留。 证据：T24-field-corrected | M13: W2-dev-20261014-5c6bc530 本地dev/Mock；不覆盖真实接口；逐步受阻见左列
A14: 表单标签和错误说明能关联到实际控件 | B14: /pcs-front/通用模板/可用性补充/标签及错误关联 | C14: [1]本地通用模板 http://127.0.0.1:5173/home 可访问；浏览器缩放100%。 [2]UI已确认键盘/读屏目标及关联方式；未确认前仅记录建议。 [3]打开新建表单并触发必填错误。 | D14: [1]检查可见标签与输入框的for/id或ARIA关联。 [2]检查字段错误与控件的描述关联。 [3]修正字段后再次检查名称、描述及焦点。 | E14: [1]控件有与可见标签一致的可访问名称，不依赖placeholder充当唯一标签。 [2]错误可通过对应描述被定位，且只关联当前字段。 [3]旧错误描述随修正清除，标签仍有效，焦点不跳到无关区域。 | F14: P2 | G14: 【设计依据】可用性补充/标签及错误关联 【测试类型】exploratory 【追溯信息】用例编号：UI-TPL-013；原检查：T13；原设计修改项：F06 【知识库依据】5.7 UXf6DG；2.1信息优先（补充） 【准入状态】本期是否纳入键盘/读屏目标及具体验收标准。 【执行说明】2026-10-13实测见右侧；受阻项逐步保留原因。 【审查方式】浏览器实际操作、截图及只读DOM量测；Mock源码仅用于确认样例限制。 【全面复核】保留可用性建议，不将无ARIA归为这份规范的硬差异。 【本次清单】S02、B013 | H14: 受阻 | I14: 2026-10-14受阻核实｜本地dev/Mock｜/demo/list/form [1–2]【已观察】可见label无for，输入无id/aria-labelledby/aria-describedby；错误为role=alert。 [3]【已实测】修正目的地后其错误清除，其余错误保留；没有执行读屏器验收。 缺少条件：可引用的UI批准基线（可访问名称、错误关联方式）及指定浏览器/读屏器组合和验收路径。 本轮证据：B20、B23；见配套报告。 | K14: 受阻 | L14: [1]【受阻】本次未完成该分支判定；历史结果另保留。 缺条件：需批准可访问性验收方式/读屏基线；本轮仅DOM关联检查 证据：T25-form-association [2]【受阻】本次未完成该分支判定；历史结果另保留。 缺条件：错误描述关联基线待确认 证据：T25-form-association [3]【受阻】本次未完成该分支判定；历史结果另保留。 缺条件：未执行修正后读屏/焦点路径 证据：无本次动态证据 | M14: W2-dev-20261014-5c6bc530 本地dev/Mock；不覆盖真实接口；逐步受阻见左列
A15: 空提交后能定位长表单中的首个错误 | B15: /pcs-front/通用模板/可用性补充/首错定位 | C15: [1]本地通用模板 http://127.0.0.1:5173/home 可访问；浏览器缩放100%。 [2]产品/UI已批准首错焦点或滚动策略；有足够长的表单使首错位于屏外。 | D15: [1]滚动到底部，在首个必填字段为空时点击保存。 [2]修正首错，再次点击保存。 [3]确认焦点位置及屏幕中的提示和底部栏。 | E15: [1]按已批准策略将首错带入可视范围或聚焦，用户无需猜测错误位置。 [2]继续定位下一处错误，已修正字段不重复抢占焦点。 [3]焦点及提示可见，不被固定栏遮挡，也不会突然跳离表单。 | F15: P2 | G15: 【设计依据】可用性补充/首错定位 【测试类型】exploratory 【追溯信息】用例编号：UI-TPL-014；原检查：T14；原设计修改项：F06 【知识库依据】5.7 UXf6DG；2.1信息优先（补充） 【准入状态】首错策略及验收口径；已观察的遮挡建议修正，不等新设计规范数值。 【执行说明】2026-10-13实测见右侧；受阻项逐步保留原因。 【审查方式】浏览器实际操作、截图及只读DOM量测；Mock源码仅用于确认样例限制。 【全面复核】保留S01建议；可见错误提示规则和首错算法要求分开。 【本次清单】S01、B014 | H15: 受阻 | I15: 2026-10-14受阻核实｜本地dev/Mock｜/demo/list/form [1]【已实测】首错在屏外时从底部鼠标保存，焦点仍在保存，首错/提示被56px顶栏遮挡。B22坐标为滚动瞬态，不冒充稳定坐标。 [2]【已实测】修正目的地再保存，日期top372.38/bottom394.38可见，旧错误消失。 缺少条件：已批准的首错聚焦或滚动策略，明确固定顶栏安全区及修正后连续错误的验收规则。 本轮证据：B21、B22、B23、B24；见配套报告。 | K15: 受阻 | L15: [1]【受阻】本次未完成该分支判定；历史结果另保留。 缺条件：首错聚焦/滚动方案仍需确认；未复测长表单首错策略 证据：无本次动态证据 [2]【受阻】本次未完成该分支判定；历史结果另保留。 缺条件：次错定位未重跑 证据：无本次动态证据 [3]【受阻】本次未完成该分支判定；历史结果另保留。 缺条件：首错策略和键盘验收基线 证据：无本次动态证据 | M15: W2-dev-20261014-5c6bc530 本地dev/Mock；不覆盖真实接口；逐步受阻见左列
A16: 模板备注达到200字上限后计数和布局一致 | B16: /pcs-front/通用模板/边界值分析/备注长度 | C16: [1]本地通用模板 http://127.0.0.1:5173/home 可访问；浏览器缩放100%。 [2]进入新建运单；该模板备注上限为200字，不作为业务字段上限。 | D16: [1]向备注填入199个汉字，查看计数。 [2]增加1个汉字，查看计数。 [3]再增加1个汉字或粘贴201个汉字。 | E16: [1]计数为199/200，输入区布局正常。 [2]计数为200/200，达到允许上限。 [3]模板按当前定义限制到200字，计数不超过200/200，未引起文本或操作区溢出。 | F16: P2 | G16: 【设计依据】边界值分析/备注长度 【测试类型】boundary 【追溯信息】用例编号：UI-TPL-015；原检查：T15；原设计修改项：无 【知识库依据】5.7 UXf6DG；模板备注上限200 【准入状态】本条修订后的步骤已覆盖。 【执行说明】2026-10-13实测见右侧；受阻项逐步保留原因。 【审查方式】浏览器实际操作、截图及只读DOM量测；Mock源码仅用于确认样例限制。 【全面复核】维持通过，注明200并非所有业务备注的统一上限。 | H16: 通过 | I16: 2026-10-14复核｜本地dev/Mock｜/demo/list/form [1]【通过】备注199字，计数199/200。 [2]【通过】加1字，计数200/200。 [3]【通过】再输入1字仍为200字/200，区域未溢出。 限制由组件执行；不声称设置了原生maxlength。 证据：V23、V24、V25、A19、A20；见配套复核证据.html。 | K16: 通过 | L16: [1]【通过】199个汉字，计数199/200。 证据：T26-note-199 [2]【通过】200个汉字，计数200/200。 证据：T26-note-200 [3]【通过】实际尝试粘贴201字后保留200字，计数200/200；属于受控截断，非原生maxlength。 证据：T26-note-201 | M16: W2-dev-20261014-5c6bc530 本地dev/Mock；不覆盖真实接口；逐步受阻见左列
... A41: 图片预览在Desktop和Tablet保留安全区并等比缩放 | B41: /pcs-front/通用模板/附件预览/安全区与关闭 | C41: [1]本地通用模板 http://127.0.0.1:5173/home 可访问；浏览器缩放100%。 [2]提供支持预览的图片样例（小图、超大横图、超大竖图）及长文件名；记录预览入口。 | D41: [1]在1440×900打开小图及超大横图、竖图预览，量测安全区和关闭位置。 [2]切换1024×768后再次打开超大图片。 [3]关闭预览，重新打开另一张图片，再滚动原页面。 | E41: [1]Desktop内容距四边至少48px，最大宽1344px/高804px，关闭按钮距边24px；图片等比缩小，不裁切、不拉伸。 [2]Tablet内容距四边至少32px，最大宽960px/高704px，关闭按钮距边20px；长文件名不盖住图片或关闭入口。 [3]可明确退出预览；无残留遮罩、旧图或滚动锁；文件列表和当前对象仍可识别。 | F41: P1 | G41: 【设计依据】边界值分析/场景法 【测试类型】boundary 【追溯信息】用例编号：UI-TPL-040；本次复查补充 【知识库依据】5.6 Z8M50N；4.5.1 cHhLBb 【准入状态】本条修订后的步骤已覆盖。 【执行说明】2026-10-13实测见右侧；受阻项逐步保留原因。 【审查方式】浏览器实际操作、截图及只读DOM量测；Mock源码仅用于确认样例限制。 【全面复核】维持通过，尺寸可计算，无需额外批准稿。 | H41: 通过 | I41: 2026-10-14复核｜本地dev/Mock｜/demo/components [1]【通过】1440×900：小图160×100不放大；横图1116.66×804、竖图556.61×804；安全区≥48px，关闭距边24px。 [2]【通过】1024×768：横图959.97×691.19、竖图487.38×704；安全区≥32px，关闭距边20px；等比缩小，长文件名不覆盖操作。 [3]【通过】关闭后预览移除、body滚动恢复；切图显示新对象。 证据：V56、V57、V58。截图、DOM及量测见配套复核证据.html。 | K41: 通过 | L41: [1]【通过】Desktop小图160×100未放大；横图2500×1800→1116.66×804，竖图1800×2600→556.61×804，等比；四边≥48，关闭距24。判定用DOM量测，截图未同步呈现浮层。 证据：C12-preview-small、C13-preview-landscape、C14a-preview-portrait-stable [2]【通过】1024×768横图959.97×691.19，四边≥32；关闭距20。 证据：C15-preview-tablet [3]【通过】关闭后预览img/close为空、body overflow恢复空值，点击上传标题后原文件列表可定位；通过DOM判定，未以不同步截图代替。 证据：C16-preview-exit | M41: W2-dev-20261014-5c6bc530 本地dev/Mock；不覆盖真实接口；逐步受阻见左列

Sheet 范围与依据
A1: SN318 W2 UI与交互用例执行说明
A3: 安排：今天（2026-10-13）输出前端页面UI规范审查和修改清单；W2（10/12—10/16）正式全面介入UI与交互。排期“UI/开”表示UI设计与开发并行，不能套用“开、测”默认周三提测规则。
A4: 执行基线：116条=76条业务候选+40条通用模板；业务候选对应38项W2“UI/开”工作包。另24项“需”仅准备需求与判据，不计本周业务UI执行范围。全面介入按页面实际交付推进，不表示已全部执行或验收。
A5: 本轮逐条核实原受阻16条：011改通过，其余15条保留受阻并写明已测步骤与具体缺少条件。通用40条汇总：通过13、不通过12、受阻15。新增J列人工二次复核，40行留空；业务76条保持原样。
A6: 通用规范已明确的UI步骤先检查；专项判据、状态或样例缺失仅阻塞相关步骤，并记录原因、所需条件与已执行证据。缺入口时整条受阻。L=字段长度上限，B=文件字节上限，K=文件数上限，N=每页条数。
A7: 只验证布局、可见状态、交互路径及恢复。算法、计价、引用规则、版本生成、数据落库和真实鉴权按原功能测试安排。
A8: 本周按工作包优先级和实际交付顺序介入：先审查、列修改项，再随修改复测；补边界、异常及缺样例步骤。每批记录Build、URL、角色、样例和截图。旧文件中的逐日顺序为历史建议，不作为本周强制提测日期。
A9: 业务表依据排期、通用规范及UI Review；本轮未读取各业务封板PRD/专项设计稿。排期“PRD”仅为来源标签。明确的通用规格可先查；业务字段、策略和状态判据缺口见每条备注，不将其作为整页通用UI审查的统一门槛。
A10: 本地dev/Mock；本轮范围为原受阻16条，能执行的步骤已续测，未切换源码或把普通成功当403/失败恢复。011使用当前固定300ms Mock验证骨架及关闭。J列人工二次复核留空，由人工填结论、复核人、日期与意见；程序结果及缺少条件在I列。
A11: 排期：https://example.invalid/source/7cdefbaffe
A12: 设计规范：https://example.invalid/source/05cc32fecc
A13: UI Review：https://example.invalid/source/e04459bb0b
A14: 二次读取规范V1.2正文仍rev5256，现行3.1嵌入色板确认链接文字#046EFC；指定UI Review视图仍显示24条（含空白）、修改时间10/12 17:23。Review具体文本及3.4/4.2/4.5.2使用首轮10/14截图；其他嵌入表及R001–R010仍为10/13参考。历史图与量测已另标日期打包，不宣称所有来源逐记录重读。
A17: 源序号 | B17: 原表行 | C17: 业务区域 | D17: 工作包 | E17: 原始来源 | F17: W2阶段 | G17: 新版用例编号 | H17: 准入状态
A18: 1 | B18: 5 | C18: 服务单元 | D18: 服务单元列表与筛选 | E18: PRD | F18: UI/开 | G18: UI-W2-01-1、UI-W2-01-2 | H18: 实际交付后介入UI；专项缺口逐步记录
A19: 2 | B19: 6 | C19: 服务单元 | D19: 服务单元批量操作 | E19: PRD | F19: UI/开 | G19: UI-W2-02-1、UI-W2-02-2 | H19: 实际交付后介入UI；专项缺口逐步记录
A20: 3 | B20: 7 | C20: 服务单元 | D20: 新增/编辑服务单元（弹窗） | E20: PRD | F20: UI/开 | G20: UI-W2-03-1、UI-W2-03-2 | H20: 实际交付后介入UI；专项缺口逐步记录
A21: 4 | B21: 8 | C21: 服务单元 | D21: 服务单元详情（只读） | E21: PRD | F21: UI/开 | G21: UI-W2-04-1、UI-W2-04-2 | H21: 实际交付后介入UI；专项缺口逐步记录
A22: 5 | B22: 9 | C22: 服务单元 | D22: 禁用编排/启用 与产品引用关系 | E22: PRD | F22: UI/开 | G22: UI-W2-05-1、UI-W2-05-2 | H22: 实际交付后介入UI；专项缺口逐步记录
A23: 6 | B23: 10 | C23: 服务单元 | D23: AI 报价建档（三套方案 + 四步流程） | E23: 原型 | F23: 需 | G23: — | H23: 需求阶段，本周不安排UI执行
A24: 7 | B24: 11 | C24: 服务组合 | D24: 服务组合列表页 | E24: PRD | F24: UI/开 | G24: UI-W2-07-1、UI-W2-07-2 | H24: 实际交付后介入UI；专项缺口逐步记录
A25: 8 | B25: 12 | C25: 服务组合 | D25: 新增/编辑服务组合 | E25: PRD | F25: UI/开 | G25: UI-W2-08-1、UI-W2-08-2 | H25: 实际交付后介入UI；专项缺口逐步记录
A26: 9 | B26: 13 | C26: 服务组合 | D26: 详情与历史版本（只读） | E26: PRD | F26: UI/开 | G26: UI-W2-09-1、UI-W2-09-2 | H26: 实际交付后介入UI；专项缺口逐步记录
A27: 10 | B27: 14 | C27: 服务组合 | D27: 删除引用校验与并发控制 | E27: PRD | F27: UI/开 | G27: UI-W2-10-1、UI-W2-10-2 | H27: 实际交付后介入UI；专项缺口逐步记录
A28: 11 | B28: 15 | C28: 策略配置 | D28: 策略列表/详情 | E28: PRD | F28: UI/开 | G28: UI-W2-11-1、UI-W2-11-2 | H28: 实际交付后介入UI；专项缺口逐步记录
A29: 12 | B29: 16 | C29: 成本价卡 | D29: 成本价卡列表页 | E29: PRD | F29: UI/开 | G29: UI-W2-12-1、UI-W2-12-2 | H29: 实际交付后介入UI；专项缺口逐步记录
... A79: 66 | B79: 70 | C79: 百运网系统对接 | D79: 同步触发节点 + 字段映射（渠道基本信息约 41 字段、渠道价格表、费用折扣、产品详情与查价 / 附加费限制）+ 供应商等基础数据获取 | E79: PRD待完善 | F79: 需 | G79: — | H79: 需求阶段，本周不安排UI执行
A83: Review引用索引（按record_id回溯）
A85: 引用ID | B85: 原优先级 | C85: 页面/模块 | D85: record_id | E85: 原始确认状态 | F85: 说明
A86: RV01 | B86: P0 | C86: 基础配置 | D86: review-67fb39add5 | E86: 设计完毕 | F86: 原始Review记录
A87: RV02 | B87: P1 | C87: 左侧菜单 | D87: review-4122ab1853 | E87: 设计完毕 | F87: 原始Review记录
A88: RV03 | B88: P1 | C88: 全局 | D88: review-294de09d51 | E88: 修改中 | F88: 无Review建议，不作独立判据
A89: RV04 | B89: P0 | C89: 全局 | D89: review-5cb0b5dcb6 | E89: 待确认 | F89: 原始Review记录
A90: RV05 | B90: P0 | C90: 服务单元 | D90: review-24220c26b9 | E90: 待确认 | F90: 原始Review记录
A91: RV06 | B91: P1 | C91: 服务单元 | D91: review-de7057751b | E91: 修改中 | F91: 原始Review记录
A92: RV07 | B92: P1 | C92: 服务单元 | D92: review-331da30eb4 | E92: 未填 | F92: 原始Review记录
A93: RV08 | B93: P1 | C93: 服务单元 | D93: review-2a5a56bb27 | E93: 设计完毕 | F93: 原始Review记录
A94: RV09 | B94: P1 | C94: 服务单元 | D94: review-c79c73690c | E94: 待确认 | F94: 原始Review记录
A95: RV10 | B95: P2 | C95: 左侧菜单 | D95: review-e3abcc238c | E95: 待确认 | F95: 原始Review记录
A96: RV11 | B96: P2 | C96: 顶部导航 | D96: review-a2a817eb2a | E96: 待确认 | F96: 原始Review记录
...

Sheet 修改清单
A1: 编号 | B1: 类型 | C1: 等级 | D1: 页面/对象 | E1: 规范依据 | F1: 实际情况 | G1: 修改或补齐建议 | H1: 验收标准 | I1: 相关用例 | J1: 证据 | K1: 状态
A2: M01 | B2: 规范差异 | C2: P2 | D2: 列表/组件页默认按钮 | E2: 规范3.4 jYqjvY、5.1 Jhut4D；R001/R007 | F2: 查询及四类普通按钮圆角2px，规定8px。032原受阻遗漏了可判定的默认态差异。 | G2: 将Arco普通按钮圆角映射到8px token，保留独立的图标/尺寸规则。 | H2: 默认32px高且圆角8px，hover/loading/disabled外形一致。 | I2: 001、031、032 | J2: E006 E049 E054 R001 | K2: 待修改
A3: M02 | B3: 规范差异 | C3: P2 | D3: 标准列表页头 | E3: 规范4.2内嵌表0rCax8：标准页头94px | F3: 实际97px，面包屑本体18px，main区57px，多出3px。 | G3: 检查面包屑行盒和inline基线，按页头层级收敛总高度。 | H3: 标准页头94px，标题/右侧操作底部对齐，窄屏无遮挡。 | I3: 002、031 | J3: E006-measurements.json E006-details.json | K3: 待修改
A4: M03 | B4: 规范差异 | C4: P2 | D4: 表格操作列 | E4: 规范5.8 tkqkxw：操作列左对齐、操作间距16px | F4: 操作内层居中，Space gap8px；左右固定列本身正常。005原第3步也要求操作左对齐，原通过漏判。 | G4: 统一操作容器左对齐及16px间距，保持固定列宽与内部滚动。 | H4: Desktop/Tablet下操作左对齐，16px间距，固定列不重叠。 | I4: 003、005、031 | J4: E006-details.json E007 E008 | K4: 待修改
A5: M04 | B5: 规范差异 | C5: P2 | D5: 表格普通正文及链接颜色 | E5: 规范3.1现行色板、5.8；正文#4B5564，链接#046EFC | F5: 二次实测普通正文#1A2130；链接#165DFF，现行3.1规定#046EFC。上一版链接子项通过有误，已纠正。 | G5: 正文映射#4B5564；链接映射color-primary #046EFC；标题和语义Tag按各自规则保留，Tag各色另补核对。 | H5: 正文#4B5564、链接#046EFC；选中/hover文字可读，Tag不被统一正文色覆盖。 | I5: 004、031 | J5: 二次A01/A03/A30；首轮V02/V06/V77；历史E006/R007 | K5: 待修改
A6: M05 | B6: 规范差异 | C6: P2 | D6: 输入占位文字 | E6: 规范5.2 placeholder #C0C4CC | F6: 组件页可编辑input的placeholder #86909C；禁用placeholder #C9CDD4。 | G6: 将placeholder及适用禁用态映射到规范token，避免Arco默认色残留。 | H6: 默认placeholder #C0C4CC；其余六态分别按5.2核对，focus光晕及错误提示保留。 | I6: 033、031 | J6: E050-input-states.json E050 E051 E052 | K6: 待修改
A7: M07 | B7: 规范差异 | C7: P2 | D7: 新建表单字段标签 | E7: 规范5.7表单标签#4B5564；R002 | F7: 1440新建表单label实际#4E5969。 | G7: 统一表单label正文色为#4B5564，红色必填星号独立。 | H7: 必填/选填标签14px正文色正确，星号与错误提示仍使用错误色。 | I7: 031 | J7: E091-form-layout.json E091 R002 | K7: 待修改
A8: M08 | B8: 规范差异 | C8: P2 | D8: Tablet表单列数 | E8: 规范4.5.2表oppJwY C3：Tablet单列 | F8: 1024、1279、768宽度表单实际仍双列。旧报告错误地按缺专项批准稿受阻。 | G8: 将768–1279的表单切为单列，按通用规范执行；无需为已有明确数值另等批准稿。 | H8: 在768、1024、1279宽度为单列，两侧16px留白，输入及底栏可达；1280以上按Desktop布局验证。 | I8: 022、037、031 | J8: E038 E087 E089 E087-breakpoint-forms.json norm-followup-oppJwY.json | K8: 待修改
A9: S01 | B9: 可用性建议 | C9: P1 | D9: 首错自动滚动 | E9: 5.7明确可见错误呈现，但未定义首错聚焦/滚动算法；属补充建议 | F9: 首错被滚到top约1px，位于56px固定顶栏下，焦点仍在保存。 | G9: 确认聚焦策略后，为首错scroll容器预留顶栏安全区并验证连续错误。 | H9: 批准策略下首错输入、标签及提示可见，修正后定位下一错不被顶栏挡住。 | I9: 014 | J9: E030 E031 E030-focus.json | K9: 待确认
A10: S02 | B10: 可用性建议 | C10: P2 | D10: 标签/错误可访问关联 | E10: 5.7未定义Input的for/id、ARIA描述或目标读屏器；属补充建议 | F10: label无for，控件无id/aria-labelledby、aria-describedby；错误role=alert。 | G10: 批准后绑定label/控件及错误描述，补目标读屏器、键盘组合验证。 | H10: 明确读出字段名、必填/错误信息；DOM关联有效，纠错后不残留旧错误。 | I10: 013 | J10: E025 E026 | K10: 待确认
A11: S03 | B11: 可用性建议 | C11: P2 | D11: 本地Mock环境提示 | E11: 环境可识别性补充建议 | F11: 基础配置页面在Mock数据环境仍显示“查看正式数据”。 | G11: 在开发预览明确显示Mock样例，避免截图被误用作真实数据验收。 | H11: dev页面可识别Mock环境；真实环境按发布配置显示。 | I11: 环境说明 | J11: E074 environment-health.json | K11: 待确认
A12: R07 | B12: 用例口径修订 | C12: P2 | D12: Text按钮loading宽度 | E12: 规范5.1、7.1及按钮附件R001 | F12: 实现与规范图均因Spin增宽。旧用例的尺寸不抖动属于附加要求，规范没有要求宽度固定。 | G12: 已修订032预期为Spin、原文字保留、不可重复触发及结束后恢复；active和完成样例仍需补。 | H12: 按真实规范验证按钮状态，不把正常增加Spin宽度判作规范冲突或实现缺陷。 | I12: 032、031 | J12: E049-buttons.json E054 R001 | K12: 已修订
... A33: B039 | B33: 执行条件待补 | C33: P1 | D33: 页面初始化返回403后显示无权限页并可返回 | E33: 7.3 2WRfcT、CIIazx；与bkjAb2操作错误区分 | F33: 【基线核实】列表正常初始化仍为86条。源码getList直接调用固定300ms成功Mock，没有初始化403切换。 [1–4]【受阻】未进入由初始化响应触发的无权限页，也未执行403→允许恢复；直接/403展示不能替代。 | G33: 页面初始化getList可控403与恢复允许的响应样例、触发入口及调用/响应过程证据。 | H33: 按当前修订用例补齐未覆盖步骤，保存同状态截图；规范已有明确规格时不再等待额外设计批准。补充验收/业务策略先记录明确基线。 | I33: UI-TPL-039 | J33: 本轮：B01、B15、B48 | K33: 待补条件
A35: 问题ID | B35: 类型 | C35: 等级 | D35: 页面/对象 | E35: 规范定位 | F35: 本次实际差异 | G35: 复现步骤 | H35: 修改/补齐建议 | I35: 验收标准 | J35: 相关用例 | K35: 证据 | L35: 整改/复测状态 | M35: 缺条件 | N35: 责任人 | O35: 排期安排 | P35: 复核状态（主数据轮次） | Q35: 复核表现/证据 | R35: 本轮Build | S35: 覆盖限制
A36: W2-R01 | B36: 已证实规范差异 | C36: P2 | D36: 模板/基础配置/按钮示例 | E36: V1.2 3.4/5.1 Jhut4D | F36: 默认按钮圆角2px，规范8px | G36: 进入列表或基础配置量测查询按钮 | H36: 检查公共按钮Token及square类覆盖 | I36: 四类默认按钮32px高、8px圆角；文字不裁切，hover/active尺寸不跳变 | J36: UI-TPL-001,UI-TPL-032,UI-M1-025 | K36: T01-list-baseline,C02-button-metrics,B46-master-common-metrics | L36: 待整改/未复测 | N36: 待分派 | O36: W2提测后整改复测；P1优先 | P36: 复测不通过（主数据范围） | Q36: 主数据查询按钮仍2px；模板范围未复测。证据C03-rate-visual。 | R36: W2-master-20261014-fd786de-8cdf1453 | S36: 仅主数据；不代测模板或其他业务页。
A37: W2-R02 | B37: 已证实规范差异 | C37: P2 | D37: /demo/list | E37: V1.2 4.2 FFO2Ix/0rCax8 | F37: 标准页头97px，规范94px | G37: 1440×900读取page-header边界 | H37: 检查标准页头垂直间距及行高 | I37: 标准页头94px、面包屑18px，标题与按钮底部对齐 | J37: UI-TPL-002 | K37: T01-list-baseline,T13-container-metrics | L37: 待整改/未复测 | N37: 待分派 | O37: W2提测后整改复测；P1优先 | P37: 本轮未复核 | Q37: 本轮没有重跑该问题对应页面或异常分支；原整改/复测状态保留。 | R37: W2-master-20261014-fd786de-8cdf1453 | S37: 未取得新的关闭证据。
A38: W2-R03 | B38: 已证实规范差异 | C38: P2 | D38: 模板操作列/汇率公共表格 | E38: V1.2 5.8 tkqkxw/IOfbnI | F38: 操作内层居中；模板gap8px，规范左对齐/16px | G38: 读取实际内层容器对齐与间距 | H38: 统一公共表格操作容器，复测固定列边界 | I38: 操作左对齐、文字按钮间距16px；Tablet固定列无重叠 | J38: UI-TPL-003,UI-TPL-005,UI-M1-025 | K38: T01-list-baseline,T13-container-metrics,B46-master-common-metrics | L38: 待整改/未复测 | N38: 待分派 | O38: W2提测后整改复测；P1优先 | P38: 复测不通过（主数据范围） | Q38: 主数据操作仍居中、gap4px；模板范围未复测。证据C03-rate-visual。 | R38: W2-master-20261014-fd786de-8cdf1453 | S38: 仅主数据；不代测模板或其他业务页。
A39: W2-R04 | B39: 已证实规范差异 | C39: P2 | D39: 模板/汇率普通正文 | E39: V1.2 3.1 hezLMm/5.8 | F39: 普通文本#1A2130，要求#4B5564 | G39: 量测目的地/日期/汇率正文 | H39: 检查正文Token被组件默认字色覆盖 | I39: 普通正文#4B5564；标题与状态语义色保留 | J39: UI-TPL-004,UI-M1-025 | K39: T01-list-baseline,B46-master-common-metrics | L39: 待整改/未复测 | N39: 待分派 | O39: W2提测后整改复测；P1优先 | P39: 复测不通过（主数据范围） | Q39: 主数据普通正文仍#1A2130；模板范围未复测。证据C03-rate-metrics。 | R39: W2-master-20261014-fd786de-8cdf1453 | S39: 仅主数据；不代测模板或其他业务页。
A40: W2-R05 | B40: 已证实规范差异 | C40: P2 | D40: /demo/list 运单链接 | E40: V1.2 3.1 28tJFI Brand Blue | F40: 链接#165DFF，规范#046EFC | G40: 读取首条运单链接计算颜色 | H40: 按现行链接Token统一 | I40: 默认链接#046EFC，hover/active使用规定色，状态含义不被覆盖 | J40: UI-TPL-004 | K40: T01-list-baseline | L40: 待整改/未复测 | N40: 待分派 | O40: W2提测后整改复测；P1优先 | P40: 本轮未复核 | Q40: 本轮没有重跑该问题对应页面或异常分支；原整改/复测状态保留。 | R40: W2-master-20261014-fd786de-8cdf1453 | S40: 未取得新的关闭证据。
A41: W2-R06 | B41: 已证实规范差异 | C41: P1 | D41: /demo/list/form Tablet | E41: V1.2 4.5.2 lfEtqB/5.7 | F41: 1024/1279仍双列，Tablet要求单列 | G41: 设置1024或1279，查看收件人/电话同一行 | H41: 检查Tablet断点与表单列配置 | I41: 768≤宽<1280采用单列、标签在上、padding16；底栏键盘可达、无根级横溢；1280恢复Desktop | J41: UI-TPL-022,UI-TPL-037 | K41: T27-form-tablet,T40-form-1279,T41-form-768 | L41: 待整改/未复测 | N41: 待分派 | O41: W2提测后整改复测；P1优先 | P41: 本轮未复核 | Q41: 本轮没有重跑该问题对应页面或异常分支；原整改/复测状态保留。 | R41: W2-master-20261014-fd786de-8cdf1453 | S41: 未取得新的关闭证据。
A42: W2-R07 | B42: 已证实交互缺陷 | C42: P1 | D42: /demo/list 查询 | E42: V1.2 2.1/7.1 局部加载 | F42: 查询期间Spin存在，但查询按钮未loading且未禁用 | G42: 输入测试词点击查询，读取早期按钮状态 | H42: 让查询按钮绑定请求状态并防止重复请求 | I42: 查询启动立即loading并不可再次触发；保留筛选，完成/失败后解除loading | J42: UI-TPL-028 | K42: T02-query-loading | L42: 待整改/未复测 | M42: 需补请求计数/slow及异常恢复样例 | N42: 待分派 | O42: W2提测后整改复测；P1优先 | P42: 本轮未复核 | Q42: 本轮没有重跑该问题对应页面或异常分支；原整改/复测状态保留。 | R42: W2-master-20261014-fd786de-8cdf1453 | S42: 未取得新的关闭证据。
